Workbook

Sheet 7-8AM
A1: 07:00 AM - 08:00 AM
A3: ROAD: NAIROBI - MOMBASA (A8) ROAD
A5: SITE: ATHI RIVER AREA, MACHAKOS COUNTY
A6: PROJECT: EXISTING COMMERCIAL DEVELOPMENT
A7: C/O: CRYSTAL RIVERS MALL
A9: TRAFFIC VOLUME COUNTS DATA (RAW DATA)
A10: 15 MINUTES VOLUMES
A12: TIME | B12: Motorcycle/Tuktuk | C12: Cars(<=5seats) | D12: Large Cars,4WD,SUVs | E12: Pickups/Vans | F12: Minibus/Matatus(<=14seat | G12: Small bus(14-33seat) | H12: Large bus(>33seat) | I12: Light Trucks(2axles) | J12: Medium Trucks(2axle,Double rear wheel) | K12: Heavy Trucks(3, 4 axles) | L12: Artics/draw-bar trucks | M12: Others (e.g tractors) | N12: TOTALS
A13: 7:00-7:15
A14: Mombasa Bound Lane 1 | B14: 37 | C14: 24 | D14: 10 | E14: 6 | F14: 10 | G14: 1 | H14: 0 | I14: 0 | J14: 3 | K14: 1 | L14: 1 | M14: 0 | N14: 37
A15: Mombasa Bound Lane 2 | B15: 16 | C15: 41 | D15: 22 | E15: 11 | F15: 9 | G15: 3 | H15: 1 | I15: 0 | J15: 21 | K15: 11 | L15: 40 | M15: 0 | N15: =SUM(B15:M15)
A16: Mombasa Bound Lane 3 | B16: 4 | C16: 47 | D16: 31 | E16: 15 | F16: 10 | G16: 0 | H16: 0 | I16: 1 | J16: 17 | K16: 6 | L16: 20 | M16: 0 | N16: =SUM(B16:M16)
A17: VEHICLES | B17: =SUM(B14:B16) | C17: =SUM(C14:C16) | D17: =SUM(D14:D16) | E17: =SUM(E14:E16) | F17: =SUM(F14:F16) | G17: =SUM(G14:G16) | H17: =SUM(H14:H16) | I17: =SUM(I14:I16) | ... M17: =SUM(M14:M16) | N17: =SUM(B17:M17)
A18: Conversion Factor | B18: 0.5 | C18: 1 | D18: 1 | E18: 1.75 | F18: 1.75 | G18: 2 | H18: 2.5 | I18: 1.25 | J18: 1.5 | K18: 2.75 | L18: 3 | M18: 2
A19: PCUs, Passenger Car Units | B19: =B17*B18 | C19: =C17*C18 | D19: =D17*D18 | E19: =E17*E18 | F19: =F17*F18 | G19: =G17*G18 | H19: =H17*H18 | I19: =I17*I18 | ... M19: =M17*M18 | N19: =SUM(B19:M19)
A23: TIME | B23: Motorcycle/Tuktuk | C23: Cars(<=5seats) | D23: Large Cars,4WD,SUVs | E23: Pickups/Vans | F23: Minibus/Matatus(<=14seat | G23: Small bus(14-33seat) | H23: Large bus(>33seat) | I23: Light Trucks(2axles) | J23: Medium Trucks(2axle,Double rear wheel) | K23: Heavy Trucks(3, 4 axles) | L23: Artics/draw-bar trucks | M23: Others (e.g tractors) | N23: TOTALS
A24: 7:15-7:30
A25: Mombasa Bound Lane 1 | B25: 42 | C25: 17 | D25: 16 | E25: 4 | F25: 9 | G25: 0 | H25: 0 | I25: 0 | J25: 4 | K25: 1 | L25: 1 | M25: 0 | N25: =SUM(B25:M25)
A26: Mombasa Bound Lane 2 | B26: 13 | C26: 28 | D26: 24 | E26: 9 | F26: 6 | G26: 3 | H26: 0 | I26: 0 | J26: 15 | K26: 11 | L26: 32 | M26: 0 | N26: =SUM(B26:M26)
A27: Mombasa Bound Lane 3 | B27: 2 | C27: 49 | D27: 28 | E27: 16 | F27: 8 | G27: 0 | H27: 0 | I27: 1 | J27: 15 | K27: 5 | L27: 16 | M27: 0 | N27: =SUM(B27:M27)
A28: VEHICLES | B28: =SUM(B25:B27) | C28: =SUM(C25:C27) | D28: =SUM(D25:D27) | E28: =SUM(E25:E27) | F28: =SUM(F25:F27) | G28: =SUM(G25:G27) | H28: =SUM(H25:H27) | I28: =SUM(I25:I27) | ... M28: =SUM(M25:M27) | N28: =SUM(B28:M28)
A29: Conversion Factor | B29: 0.5 | C29: 1 | D29: 1 | E29: 1.75 | F29: 1.75 | G29: 2 | H29: 2.5 | I29: 1.25 | J29: 1.5 | K29: 2.75 | L29: 3 | M29: 2
A30: PCUs, Passenger Car Units | B30: =B28*B29 | C30: =C28*C29 | D30: =D28*D29 | E30: =E28*E29 | F30: =F28*F29 | G30: =G28*G29 | H30: =H28*H29 | I30: =I28*I29 | ... M30: =M28*M29 | N30: =SUM(B30:M30)
A34: TIME | B34: Motorcycle/Tuktuk | C34: Cars(<=5seats) | D34: Large Cars,4WD,SUVs | E34: Pickups/Vans | F34: Minibus/Matatus(<=14seat | G34: Small bus(14-33seat) | H34: Large bus(>33seat) | I34: Light Trucks(2axles) | J34: Medium Trucks(2axle,Double rear wheel) | K34: Heavy Trucks(3, 4 axles) | L34: Artics/draw-bar trucks | M34: Others (e.g tractors) | N34: TOTALS
A35: 7:30-7:45
A36: Mombasa Bound Lane 1 | B36: 32 | C36: 19 | D36: 14 | E36: 5 | F36: 7 | G36: 1 | H36: 0 | I36: 0 | J36: 4 | K36: 0 | L36: 1 | M36: 0 | N36: =SUM(B36:M36)
A37: Mombasa Bound Lane 2 | B37: 17 | C37: 45 | D37: 23 | E37: 10 | F37: 6 | G37: 3 | H37: 1 | I37: 0 | J37: 20 | K37: 10 | L37: 36 | M37: 0 | N37: =SUM(B37:M37)
A38: Mombasa Bound Lane 3 | B38: 3 | C38: 35 | D38: 29 | E38: 10 | F38: 7 | G38: 0 | H38: 0 | I38: 1 | J38: 13 | K38: 4 | L38: 17 | M38: 0 | N38: =SUM(B38:M38)
A39: VEHICLES | B39: =SUM(B36:B38) | C39: =SUM(C36:C38) | D39: =SUM(D36:D38) | E39: =SUM(E36:E38) | F39: =SUM(F36:F38) | G39: =SUM(G36:G38) | H39: =SUM(H36:H38) | I39: =SUM(I36:I38) | ... M39: =SUM(M36:M38) | N39: =SUM(B39:M39)
A40: Conversion Factor | B40: 0.5 | C40: 1 | D40: 1 | E40: 1.75 | F40: 1.75 | G40: 2 | H40: 2.5 | I40: 1.25 | J40: 1.5 | K40: 2.75 | L40: 3 | M40: 2
A41: PCUs, Passenger Car Units | B41: =B39*B40 | C41: =C39*C40 | D41: =D39*D40 | E41: =E39*E40 | F41: =F39*F40 | G41: =G39*G40 | H41: =H39*H40 | I41: =I39*I40 | ... M41: =M39*M40 | N41: =SUM(B41:M41)
A45: TIME | B45: Motorcycle/Tuktuk | C45: Cars(<=5seats) | D45: Large Cars,4WD,SUVs | E45: Pickups/Vans | F45: Minibus/Matatus(<=14seat | G45: Small bus(14-33seat) | H45: Large bus(>33seat) | I45: Light Trucks(2axles) | J45: Medium Trucks(2axle,Double rear wheel) | K45: Heavy Trucks(3, 4 axles) | L45: Artics/draw-bar trucks | M45: Others (e.g tractors) | N45: TOTALS
A46: 7:45-8:00
A47: Mombasa Bound Lane 1 | B47: 27 | C47: 33 | D47: 13 | E47: 4 | F47: 7 | G47: 2 | H47: 2 | I47: 2 | J47: 8 | K47: 3 | L47: 2 | M47: 1 | N47: =SUM(B47:M47)
A48: Mombasa Bound Lane 2 | B48: 15 | C48: 28 | D48: 13 | E48: 6 | F48: 12 | G48: 4 | H48: 2 | I48: 3 | J48: 29 | K48: 6 | L48: 34 | M48: 1 | N48: =SUM(B48:M48)
A49: Mombasa Bound Lane 3 | B49: 5 | C49: 33 | D49: 38 | E49: 11 | F49: 9 | G49: 4 | H49: 2 | I49: 2 | J49: 24 | K49: 5 | L49: 20 | M49: 1 | N49: =SUM(B49:M49)
A50: VEHICLES | B50: =SUM(B47:B49) | C50: =SUM(C47:C49) | D50: =SUM(D47:D49) | E50: =SUM(E47:E49) | F50: =SUM(F47:F49) | G50: =SUM(G47:G49) | H50: =SUM(H47:H49) | I50: =SUM(I47:I49) | ... M50: =SUM(M47:M49) | N50: =SUM(B50:M50)
A51: Conversion Factor | B51: 0.5 | C51: 1 | D51: 1 | E51: 1.75 | F51: 1.75 | G51: 2 | H51: 2.5 | I51: 1.25 | J51: 1.5 | K51: 2.75 | L51: 3 | M51: 2
A52: PCUs, Passenger Car Units | B52: =B50*B51 | C52: =C50*C51 | D52: =D50*D51 | E52: =E50*E51 | F52: =F50*F51 | G52: =G50*G51 | H52: =H50*H51 | I52: =I50*I51 | ... M52: =M50*M51 | N52: =SUM(B52:M52)
A56: HOURLY (1HR) SUMMARY
...

Sheet 8-9 AM
A1: 08:00 AM - 09:00 AM
A3: ='7-8AM'!A3:N3
A5: ='7-8AM'!A5:N5
A6: ='7-8AM'!A6:N6
A7: ='7-8AM'!A7:N7
A9: TRAFFIC VOLUME COUNTS DATA (RAW DATA)
A10: 15 MINUTES VOLUMES
A12: TIME | B12: Motorcycle/Tuktuk | C12: Cars(<=5seats) | D12: Large Cars,4WD,SUVs | E12: Pickups/Vans | F12: Minibus/Matatus(<=14seat | G12: Small bus(14-33seat) | H12: Large bus(>33seat) | I12: Light Trucks(2axles) | J12: Medium Trucks(2axle,Double rear wheel) | K12: Heavy Trucks(3, 4 axles) | L12: Artics/draw-bar trucks | M12: Others (e.g tractors) | N12: TOTALS
A13: 8:00-8:15
A14: Mombasa Bound Lane 1 | B14: 35 | C14: 19 | D14: 9 | E14: 1 | F14: 6 | G14: 1 | H14: 0 | I14: 1 | J14: 0 | K14: 0 | L14: 0 | M14: 0 | N14: =SUM(B14:M14)
A15: Mombasa Bound Lane 2 | B15: 9 | C15: 27 | D15: 20 | E15: 8 | F15: 6 | G15: 3 | H15: 0 | I15: 0 | J15: 9 | K15: 4 | L15: 22 | M15: 1 | N15: =SUM(B15:M15)
A16: Mombasa Bound Lane 3 | B16: 5 | C16: 46 | D16: 36 | E16: 5 | F16: 7 | G16: 0 | H16: 1 | I16: 0 | J16: 3 | K16: 4 | L16: 8 | M16: 0 | N16: =SUM(B16:M16)
A17: VEHICLES | B17: =SUM(B14:B16) | C17: =SUM(C14:C16) | D17: =SUM(D14:D16) | E17: =SUM(E14:E16) | F17: =SUM(F14:F16) | G17: =SUM(G14:G16) | H17: =SUM(H14:H16) | I17: =SUM(I14:I16) | ... M17: =SUM(M14:M16) | N17: =SUM(B17:M17)
A18: Conversion Factor | B18: 0.5 | C18: 1 | D18: 1 | E18: 1.75 | F18: 1.75 | G18: 2 | H18: 2.5 | I18: 1.25 | J18: 1.5 | K18: 2.75 | L18: 3 | M18: 2
A19: PCUs, Passenger Car Units | B19: =B17*B18 | C19: =C17*C18 | D19: =D17*D18 | E19: =E17*E18 | F19: =F17*F18 | G19: =G17*G18 | H19: =H17*H18 | I19: =I17*I18 | ... M19: =M17*M18 | N19: =SUM(B19:M19)
A23: TIME | B23: Motorcycle/Tuktuk | C23: Cars(<=5seats) | D23: Large Cars,4WD,SUVs | E23: Pickups/Vans | F23: Minibus/Matatus(<=14seat | G23: Small bus(14-33seat) | H23: Large bus(>33seat) | I23: Light Trucks(2axles) | J23: Medium Trucks(2axle,Double rear wheel) | K23: Heavy Trucks(3, 4 axles) | L23: Artics/draw-bar trucks | M23: Others (e.g tractors) | N23: TOTALS
A24: 8:15-8:30
A25: Mombasa Bound Lane 1 | B25: 32 | C25: 13 | D25: 8 | E25: 2 | F25: 4 | G25: 0 | H25: 0 | I25: 0 | J25: 2 | K25: 1 | L25: 0 | M25: 0 | N25: =SUM(B25:M25)
A26: Mombasa Bound Lane 2 | B26: 5 | C26: 23 | D26: 22 | E26: 3 | F26: 8 | G26: 2 | H26: 0 | I26: 0 | J26: 13 | K26: 9 | L26: 23 | M26: 0 | N26: =SUM(B26:M26)
A27: Mombasa Bound Lane 3 | B27: 1 | C27: 31 | D27: 15 | E27: 4 | F27: 3 | G27: 1 | H27: 0 | I27: 0 | J27: 16 | K27: 1 | L27: 12 | M27: 0 | N27: =SUM(B27:M27)
A28: VEHICLES | B28: =SUM(B25:B27) | C28: =SUM(C25:C27) | D28: =SUM(D25:D27) | E28: =SUM(E25:E27) | F28: =SUM(F25:F27) | G28: =SUM(G25:G27) | H28: =SUM(H25:H27) | I28: =SUM(I25:I27) | ... M28: =SUM(M25:M27) | N28: =SUM(B28:M28)
A29: Conversion Factor | B29: 0.5 | C29: 1 | D29: 1 | E29: 1.75 | F29: 1.75 | G29: 2 | H29: 2.5 | I29: 1.25 | J29: 1.5 | K29: 2.75 | L29: 3 | M29: 2
A30: PCUs, Passenger Car Units | B30: =B28*B29 | C30: =C28*C29 | D30: =D28*D29 | E30: =E28*E29 | F30: =F28*F29 | G30: =G28*G29 | H30: =H28*H29 | I30: =I28*I29 | ... M30: =M28*M29 | N30: =SUM(B30:M30)
A34: TIME | B34: Motorcycle/Tuktuk | C34: Cars(<=5seats) | D34: Large Cars,4WD,SUVs | E34: Pickups/Vans | F34: Minibus/Matatus(<=14seat | G34: Small bus(14-33seat) | H34: Large bus(>33seat) | I34: Light Trucks(2axles) | J34: Medium Trucks(2axle,Double rear wheel) | K34: Heavy Trucks(3, 4 axles) | L34: Artics/draw-bar trucks | M34: Others (e.g tractors) | N34: TOTALS
A35: 8:30-8:45
A36: Mombasa Bound Lane 1 | B36: 28 | C36: 19 | D36: 5 | E36: 1 | F36: 9 | G36: 1 | H36: 0 | I36: 0 | J36: 5 | K36: 1 | L36: 0 | M36: 0 | N36: =SUM(B36:M36)
A37: Mombasa Bound Lane 2 | B37: 4 | C37: 25 | D37: 19 | E37: 8 | F37: 0 | G37: 0 | H37: 0 | I37: 0 | J37: 18 | K37: 7 | L37: 14 | M37: 0 | N37: =SUM(B37:M37)
A38: Mombasa Bound Lane 3 | B38: 5 | C38: 31 | D38: 59 | E38: 19 | F38: 13 | G38: 0 | H38: 0 | I38: 1 | J38: 13 | K38: 7 | L38: 14 | M38: 0 | N38: =SUM(B38:M38)
A39: VEHICLES | B39: =SUM(B36:B38) | C39: =SUM(C36:C38) | D39: =SUM(D36:D38) | E39: =SUM(E36:E38) | F39: =SUM(F36:F38) | G39: =SUM(G36:G38) | H39: =SUM(H36:H38) | I39: =SUM(I36:I38) | ... M39: =SUM(M36:M38) | N39: =SUM(B39:M39)
A40: Conversion Factor | B40: 0.5 | C40: 1 | D40: 1 | E40: 1.75 | F40: 1.75 | G40: 2 | H40: 2.5 | I40: 1.25 | J40: 1.5 | K40: 2.75 | L40: 3 | M40: 2
A41: PCUs, Passenger Car Units | B41: =B39*B40 | C41: =C39*C40 | D41: =D39*D40 | E41: =E39*E40 | F41: =F39*F40 | G41: =G39*G40 | H41: =H39*H40 | I41: =I39*I40 | ... M41: =M39*M40 | N41: =SUM(B41:M41)
A45: TIME | B45: Motorcycle/Tuktuk | C45: Cars(<=5seats) | D45: Large Cars,4WD,SUVs | E45: Pickups/Vans | F45: Minibus/Matatus(<=14seat | G45: Small bus(14-33seat) | H45: Large bus(>33seat) | I45: Light Trucks(2axles) | J45: Medium Trucks(2axle,Double rear wheel) | K45: Heavy Trucks(3, 4 axles) | L45: Artics/draw-bar trucks | M45: Others (e.g tractors) | N45: TOTALS
A46: 8:45-9:00
A47: Mombasa Bound Lane 1 | B47: 24 | C47: 18 | D47: 6 | E47: 5 | F47: 8 | G47: 1 | H47: 0 | I47: 2 | J47: 1 | K47: 0 | L47: 1 | M47: 0 | N47: =SUM(B47:M47)
A48: Mombasa Bound Lane 2 | B48: 2 | C48: 31 | D48: 19 | E48: 12 | F48: 7 | G48: 0 | H48: 0 | I48: 0 | J48: 23 | K48: 12 | L48: 12 | M48: 0 | N48: =SUM(B48:M48)
A49: Mombasa Bound Lane 3 | B49: 0 | C49: 32 | D49: 44 | E49: 17 | F49: 2 | G49: 1 | H49: 0 | I49: 2 | J49: 13 | K49: 16 | L49: 18 | M49: 0 | N49: =SUM(B49:M49)
A50: VEHICLES | B50: =SUM(B47:B49) | C50: =SUM(C47:C49) | D50: =SUM(D47:D49) | E50: =SUM(E47:E49) | F50: =SUM(F47:F49) | G50: =SUM(G47:G49) | H50: =SUM(H47:H49) | I50: =SUM(I47:I49) | ... M50: =SUM(M47:M49) | N50: =SUM(B50:M50)
A51: Conversion Factor | B51: 0.5 | C51: 1 | D51: 1 | E51: 1.75 | F51: 1.75 | G51: 2 | H51: 2.5 | I51: 1.25 | J51: 1.5 | K51: 2.75 | L51: 3 | M51: 2
A52: PCUs, Passenger Car Units | B52: =B50*B51 | C52: =C50*C51 | D52: =D50*D51 | E52: =E50*E51 | F52: =F50*F51 | G52: =G50*G51 | H52: =H50*H51 | I52: =I50*I51 | ... M52: =M50*M51 | N52: =SUM(B52:M52)
A56: HOURLY (1HR) SUMMARY
...

Sheet 9-10AM
A1: 09:00 AM - 10:00 AM
A3: ='7-8AM'!A3:N3
A5: ='7-8AM'!A5:N5
A6: ='7-8AM'!A6:N6
A7: ='7-8AM'!A7:N7
A9: TRAFFIC VOLUME COUNTS DATA (RAW DATA)
A10: 15 MINUTES VOLUMES
A12: TIME | B12: Motorcycle/Tuktuk | C12: Cars(<=5seats) | D12: Large Cars,4WD,SUVs | E12: Pickups/Vans | F12: Minibus/Matatus(<=14seat | G12: Small bus(14-33seat) | H12: Large bus(>33seat) | I12: Light Trucks(2axles) | J12: Medium Trucks(2axle,Double rear wheel) | K12: Heavy Trucks(3, 4 axles) | L12: Artics/draw-bar trucks | M12: Others (e.g tractors) | N12: TOTALS
A13: 9:00-9:15
A14: Mombasa Bound Lane 1 | B14: 40 | C14: 30 | D14: 10 | E14: 3 | F14: 7 | G14: 1 | H14: 0 | I14: 0 | J14: 4 | K14: 1 | L14: 1 | M14: 0 | N14: =SUM(B14:M14)
A15: Mombasa Bound Lane 2 | B15: 11 | C15: 21 | D15: 15 | E15: 7 | F15: 5 | G15: 3 | H15: 0 | I15: 0 | J15: 25 | K15: 9 | L15: 32 | M15: 0 | N15: =SUM(B15:M15)
A16: Mombasa Bound Lane 3 | B16: 3 | C16: 37 | D16: 24 | E16: 12 | F16: 11 | G16: 1 | H16: 0 | I16: 1 | J16: 13 | K16: 4 | L16: 12 | M16: 0 | N16: =SUM(B16:M16)
A17: VEHICLES | B17: =SUM(B14:B16) | C17: =SUM(C14:C16) | D17: =SUM(D14:D16) | E17: =SUM(E14:E16) | F17: =SUM(F14:F16) | G17: =SUM(G14:G16) | H17: =SUM(H14:H16) | I17: =SUM(I14:I16) | ... M17: =SUM(M14:M16) | N17: =SUM(B17:M17)
A18: Conversion Factor | B18: 0.5 | C18: 1 | D18: 1 | E18: 1.75 | F18: 1.75 | G18: 2 | H18: 2.5 | I18: 1.25 | J18: 1.5 | K18: 2.75 | L18: 3 | M18: 2
A19: PCUs, Passenger Car Units | B19: =B17*B18 | C19: =C17*C18 | D19: =D17*D18 | E19: =E17*E18 | F19: =F17*F18 | G19: =G17*G18 | H19: =H17*H18 | I19: =I17*I18 | ... M19: =M17*M18 | N19: =SUM(B19:M19)
A23: TIME | B23: Motorcycle/Tuktuk | C23: Cars(<=5seats) | D23: Large Cars,4WD,SUVs | E23: Pickups/Vans | F23: Minibus/Matatus(<=14seat | G23: Small bus(14-33seat) | H23: Large bus(>33seat) | I23: Light Trucks(2axles) | J23: Medium Trucks(2axle,Double rear wheel) | K23: Heavy Trucks(3, 4 axles) | L23: Artics/draw-bar trucks | M23: Others (e.g tractors) | N23: TOTALS
A24: 9:15-9:30
A25: Mombasa Bound Lane 1 | B25: 31 | C25: 29 | D25: 14 | E25: 3 | F25: 9 | G25: 1 | H25: 0 | I25: 0 | J25: 4 | K25: 0 | L25: 1 | M25: 0 | N25: =SUM(B25:M25)
A26: Mombasa Bound Lane 2 | B26: 12 | C26: 31 | D26: 24 | E26: 8 | F26: 5 | G26: 2 | H26: 0 | I26: 0 | J26: 23 | K26: 8 | L26: 32 | M26: 0 | N26: =SUM(B26:M26)
A27: Mombasa Bound Lane 3 | B27: 3 | C27: 44 | D27: 39 | E27: 8 | F27: 8 | G27: 0 | H27: 0 | I27: 0 | J27: 13 | K27: 5 | L27: 13 | M27: 0 | N27: =SUM(B27:M27)
A28: VEHICLES | B28: =SUM(B25:B27) | C28: =SUM(C25:C27) | D28: =SUM(D25:D27) | E28: =SUM(E25:E27) | F28: =SUM(F25:F27) | G28: =SUM(G25:G27) | H28: =SUM(H25:H27) | I28: =SUM(I25:I27) | ... M28: =SUM(M25:M27) | N28: =SUM(B28:M28)
A29: Conversion Factor | B29: 0.5 | C29: 1 | D29: 1 | E29: 1.75 | F29: 1.75 | G29: 2 | H29: 2.5 | I29: 1.25 | J29: 1.5 | K29: 2.75 | L29: 3 | M29: 2
A30: PCUs, Passenger Car Units | B30: =B28*B29 | C30: =C28*C29 | D30: =D28*D29 | E30: =E28*E29 | F30: =F28*F29 | G30: =G28*G29 | H30: =H28*H29 | I30: =I28*I29 | ... M30: =M28*M29 | N30: =SUM(B30:M30)
A34: TIME | B34: Motorcycle/Tuktuk | C34: Cars(<=5seats) | D34: Large Cars,4WD,SUVs | E34: Pickups/Vans | F34: Minibus/Matatus(<=14seat | G34: Small bus(14-33seat) | H34: Large bus(>33seat) | I34: Light Trucks(2axles) | J34: Medium Trucks(2axle,Double rear wheel) | K34: Heavy Trucks(3, 4 axles) | L34: Artics/draw-bar trucks | M34: Others (e.g tractors) | N34: TOTALS
A35: 9:30-9:45
A36: Mombasa Bound Lane 1 | B36: 35 | C36: 17 | D36: 14 | E36: 3 | F36: 7 | G36: 1 | H36: 0 | I36: 0 | J36: 5 | K36: 1 | L36: 1 | M36: 0 | N36: =SUM(B36:M36)
A37: Mombasa Bound Lane 2 | B37: 13 | C37: 28 | D37: 22 | E37: 6 | F37: 4 | G37: 2 | H37: 1 | I37: 0 | J37: 22 | K37: 6 | L37: 33 | M37: 0 | N37: =SUM(B37:M37)
A38: Mombasa Bound Lane 3 | B38: 3 | C38: 61 | D38: 35 | E38: 7 | F38: 7 | G38: 0 | H38: 0 | I38: 1 | J38: 12 | K38: 5 | L38: 16 | M38: 0 | N38: =SUM(B38:M38)
A39: VEHICLES | B39: =SUM(B36:B38) | C39: =SUM(C36:C38) | D39: =SUM(D36:D38) | E39: =SUM(E36:E38) | F39: =SUM(F36:F38) | G39: =SUM(G36:G38) | H39: =SUM(H36:H38) | I39: =SUM(I36:I38) | J39: =SUM(J36:J38) | K39: =J39 | L39: =SUM(L36:L38) | M39: =SUM(M36:M38) | N39: =SUM(B39:M39)
A40: Conversion Factor | B40: 0.5 | C40: 1 | D40: 1 | E40: 1.75 | F40: 1.75 | G40: 2 | H40: 2.5 | I40: 1.25 | J40: 1.5 | K40: 2.75 | L40: 3 | M40: 2
A41: PCUs, Passenger Car Units | B41: =B39*B40 | C41: =C39*C40 | D41: =D39*D40 | E41: =E39*E40 | F41: =F39*F40 | G41: =G39*G40 | H41: =H39*H40 | I41: =I39*I40 | ... M41: =M39*M40 | N41: =SUM(B41:M41)
A45: TIME | B45: Motorcycle/Tuktuk | C45: Cars(<=5seats) | D45: Large Cars,4WD,SUVs | E45: Pickups/Vans | F45: Minibus/Matatus(<=14seat | G45: Small bus(14-33seat) | H45: Large bus(>33seat) | I45: Light Trucks(2axles) | J45: Medium Trucks(2axle,Double rear wheel) | K45: Heavy Trucks(3, 4 axles) | L45: Artics/draw-bar trucks | M45: Others (e.g tractors) | N45: TOTALS
A46: 9:45-10:00
A47: Mombasa Bound Lane 1 | B47: 20 | C47: 18 | D47: 22 | E47: 5 | F47: 6 | G47: 2 | H47: 2 | I47: 2 | J47: 3 | K47: 3 | L47: 3 | M47: 1 | N47: =SUM(B47:M47)
A48: Mombasa Bound Lane 2 | B48: 23 | C48: 20 | D48: 24 | E48: 11 | F48: 12 | G48: 5 | H48: 3 | I48: 3 | J48: 8 | K48: 11 | L48: 30 | M48: 1 | N48: =SUM(B48:M48)
A49: Mombasa Bound Lane 3 | B49: 3 | C49: 48 | D49: 29 | E49: 16 | F49: 10 | G49: 4 | H49: 2 | I49: 2 | J49: 13 | K49: 8 | L49: 27 | M49: 1 | N49: =SUM(B49:M49)
A50: VEHICLES | B50: =SUM(B47:B49) | C50: =SUM(C47:C49) | D50: =SUM(D47:D49) | E50: =SUM(E47:E49) | F50: =SUM(F47:F49) | G50: =SUM(G47:G49) | H50: =SUM(H47:H49) | I50: =SUM(I47:I49) | ... M50: =SUM(M47:M49) | N50: =SUM(B50:M50)
A51: Conversion Factor | B51: 0.5 | C51: 1 | D51: 1 | E51: 1.75 | F51: 1.75 | G51: 2 | H51: 2.5 | I51: 1.25 | J51: 1.5 | K51: 2.75 | L51: 3 | M51: 2
A52: PCUs, Passenger Car Units | B52: =B50*B51 | C52: =C50*C51 | D52: =D50*D51 | E52: =E50*E51 | F52: =F50*F51 | G52: =G50*G51 | H52: =H50*H51 | I52: =I50*I51 | ... M52: =M50*M51 | N52: =SUM(B52:M52)
A56: HOURLY (1HR) SUMMARY
...

Sheet 10-11AM
A1: 10:00 AM - 11:00 AM
A3: ='7-8AM'!A3:N3
A5: ='7-8AM'!A5:N5
A6: ='7-8AM'!A6:N6
A7: ='7-8AM'!A7:N7
A9: TRAFFIC VOLUME COUNTS DATA (RAW DATA)
A10: 15 MINUTES VOLUMES
A12: TIME | B12: Motorcycle/Tuktuk | C12: Cars(<=5seats) | D12: Large Cars,4WD,SUVs | E12: Pickups/Vans | F12: Minibus/Matatus(<=14seat | G12: Small bus(14-33seat) | H12: Large bus(>33seat) | I12: Light Trucks(2axles) | J12: Medium Trucks(2axle,Double rear wheel) | K12: Heavy Trucks(3, 4 axles) | L12: Artics/draw-bar trucks | M12: Others (e.g tractors) | N12: TOTALS
A13: 10:00-10:15
A14: Mombasa Bound Lane 1 | B14: 24 | C14: 20 | D14: 10 | E14: 2 | F14: 6 | G14: 0 | H14: 0 | I14: 0 | J14: 2 | K14: 1 | L14: 1 | M14: 0 | N14: =SUM(B14:M14)
A15: Mombasa Bound Lane 2 | B15: 13 | C15: 27 | D15: 12 | E15: 7 | F15: 6 | G15: 2 | H15: 1 | I15: 0 | J15: 14 | K15: 10 | L15: 30 | M15: 0 | N15: =SUM(B15:M15)
A16: Mombasa Bound Lane 3 | B16: 2 | C16: 37 | D16: 22 | E16: 14 | F16: 5 | G16: 1 | H16: 0 | I16: 0 | J16: 9 | K16: 5 | L16: 22 | M16: 0 | N16: =SUM(B16:M16)
A17: VEHICLES | B17: =SUM(B14:B16) | C17: =SUM(C14:C16) | D17: =SUM(D14:D16) | E17: =SUM(E14:E16) | F17: =SUM(F14:F16) | G17: =SUM(G14:G16) | H17: =SUM(H14:H16) | I17: =SUM(I14:I16) | ... M17: =SUM(M14:M16) | N17: =SUM(B17:M17)
A18: Conversion Factor | B18: 0.5 | C18: 1 | D18: 1 | E18: 1.75 | F18: 1.75 | G18: 2 | H18: 2.5 | I18: 1.25 | J18: 1.5 | K18: 2.75 | L18: 3 | M18: 2
A19: PCUs, Passenger Car Units | B19: =B17*B18 | C19: =C17*C18 | D19: =D17*D18 | E19: =E17*E18 | F19: =F17*F18 | G19: =G17*G18 | H19: =H17*H18 | I19: =I17*I18 | ... M19: =M17*M18 | N19: =SUM(B19:M19)
A23: TIME | B23: Motorcycle/Tuktuk | C23: Cars(<=5seats) | D23: Large Cars,4WD,SUVs | E23: Pickups/Vans | F23: Minibus/Matatus(<=14seat | G23: Small bus(14-33seat) | H23: Large bus(>33seat) | I23: Light Trucks(2axles) | J23: Medium Trucks(2axle,Double rear wheel) | K23: Heavy Trucks(3, 4 axles) | L23: Artics/draw-bar trucks | M23: Others (e.g tractors) | N23: TOTALS
A24: 10:15-10:30
A25: Mombasa Bound Lane 1 | B25: 29 | C25: 17 | D25: 8 | E25: 3 | F25: 5 | G25: 1 | H25: 0 | I25: 0 | J25: 3 | K25: 1 | L25: 1 | M25: 0 | N25: =SUM(B25:M25)
A26: Mombasa Bound Lane 2 | B26: 14 | C26: 22 | D26: 14 | E26: 8 | F26: 7 | G26: 1 | H26: 0 | I26: 0 | J26: 16 | K26: 9 | L26: 22 | M26: 0 | N26: =SUM(B26:M26)
A27: Mombasa Bound Lane 3 | B27: 2 | C27: 52 | D27: 33 | E27: 9 | F27: 6 | G27: 0 | H27: 0 | I27: 0 | J27: 15 | K27: 6 | L27: 15 | M27: 0 | N27: =SUM(B27:M27)
A28: VEHICLES | B28: =SUM(B25:B27) | C28: =SUM(C25:C27) | D28: =SUM(D25:D27) | E28: =SUM(E25:E27) | F28: =SUM(F25:F27) | G28: =SUM(G25:G27) | H28: =SUM(H25:H27) | I28: =SUM(I25:I27) | ... M28: =SUM(M25:M27) | N28: =SUM(B28:M28)
A29: Conversion Factor | B29: 0.5 | C29: 1 | D29: 1 | E29: 1.75 | F29: 1.75 | G29: 2 | H29: 2.5 | I29: 1.25 | J29: 1.5 | K29: 2.75 | L29: 3 | M29: 2
A30: PCUs, Passenger Car Units | B30: =B28*B29 | C30: =C28*C29 | D30: =D28*D29 | E30: =E28*E29 | F30: =F28*F29 | G30: =G28*G29 | H30: =H28*H29 | I30: =I28*I29 | ... M30: =M28*M29 | N30: =SUM(B30:M30)
A34: TIME | B34: Motorcycle/Tuktuk | C34: Cars(<=5seats) | D34: Large Cars,4WD,SUVs | E34: Pickups/Vans | F34: Minibus/Matatus(<=14seat | G34: Small bus(14-33seat) | H34: Large bus(>33seat) | I34: Light Trucks(2axles) | J34: Medium Trucks(2axle,Double rear wheel) | K34: Heavy Trucks(3, 4 axles) | L34: Artics/draw-bar trucks | M34: Others (e.g tractors) | N34: TOTALS
A35: 10:30-10:45
A36: Mombasa Bound Lane 1 | B36: 32 | C36: 15 | D36: 9 | E36: 3 | F36: 6 | G36: 0 | H36: 0 | I36: 0 | J36: 4 | K36: 1 | L36: 1 | M36: 0 | N36: =SUM(B36:M36)
A37: Mombasa Bound Lane 2 | B37: 12 | C37: 29 | D37: 20 | E37: 6 | F37: 5 | G37: 2 | H37: 0 | I37: 0 | J37: 16 | K37: 9 | L37: 31 | M37: 0 | N37: =SUM(B37:M37)
A38: Mombasa Bound Lane 3 | B38: 1 | C38: 39 | D38: 21 | E38: 12 | F38: 8 | G38: 1 | H38: 0 | I38: 1 | J38: 10 | K38: 5 | L38: 17 | M38: 0 | N38: =SUM(B38:M38)
A39: VEHICLES | B39: =SUM(B36:B38) | C39: =SUM(C36:C38) | D39: =SUM(D36:D38) | E39: =SUM(E36:E38) | F39: =SUM(F36:F38) | G39: =SUM(G36:G38) | H39: =SUM(H36:H38) | I39: =SUM(I36:I38) | ... M39: =SUM(M36:M38) | N39: =SUM(B39:M39)
A40: Conversion Factor | B40: 0.5 | C40: 1 | D40: 1 | E40: 1.75 | F40: 1.75 | G40: 2 | H40: 2.5 | I40: 1.25 | J40: 1.5 | K40: 2.75 | L40: 3 | M40: 2
A41: PCUs, Passenger Car Units | B41: =B39*B40 | C41: =C39*C40 | D41: =D39*D40 | E41: =E39*E40 | F41: =F39*F40 | G41: =G39*G40 | H41: =H39*H40 | I41: =I39*I40 | ... M41: =M39*M40 | N41: =SUM(B41:M41)
A45: TIME | B45: Motorcycle/Tuktuk | C45: Cars(<=5seats) | D45: Large Cars,4WD,SUVs | E45: Pickups/Vans | F45: Minibus/Matatus(<=14seat | G45: Small bus(14-33seat) | H45: Large bus(>33seat) | I45: Light Trucks(2axles) | J45: Medium Trucks(2axle,Double rear wheel) | K45: Heavy Trucks(3, 4 axles) | L45: Artics/draw-bar trucks | M45: Others (e.g tractors) | N45: TOTALS
A46: 10:45-11:00
A47: Mombasa Bound Lane 1 | B47: 46 | C47: 34 | D47: 18 | E47: 6 | F47: 9 | G47: 3 | H47: 2 | I47: 2 | J47: 4 | K47: 2 | L47: 2 | M47: 1 | N47: =SUM(B47:M47)
A48: Mombasa Bound Lane 2 | B48: 8 | C48: 29 | D48: 20 | E48: 6 | F48: 8 | G48: 4 | H48: 3 | I48: 3 | J48: 15 | K48: 9 | L48: 20 | M48: 1 | N48: =SUM(B48:M48)
A49: Mombasa Bound Lane 3 | B49: 4 | C49: 36 | D49: 48 | E49: 11 | F49: 12 | G49: 2 | H49: 2 | I49: 3 | J49: 17 | K49: 5 | L49: 16 | M49: 1 | N49: =SUM(B49:M49)
A50: VEHICLES | B50: =SUM(B47:B49) | C50: =SUM(C47:C49) | D50: =SUM(D47:D49) | E50: =SUM(E47:E49) | F50: =SUM(F47:F49) | G50: =SUM(G47:G49) | H50: =SUM(H47:H49) | I50: =SUM(I47:I49) | ... M50: =SUM(M47:M49) | N50: =SUM(B50:M50)
A51: Conversion Factor | B51: 0.5 | C51: 1 | D51: 1 | E51: 1.75 | F51: 1.75 | G51: 2 | H51: 2.5 | I51: 1.25 | J51: 1.5 | K51: 2.75 | L51: 3 | M51: 2
A52: PCUs, Passenger Car Units | B52: =B50*B51 | C52: =C50*C51 | D52: =D50*D51 | E52: =E50*E51 | F52: =F50*F51 | G52: =G50*G51 | H52: =H50*H51 | I52: =I50*I51 | ... M52: =M50*M51 | N52: =SUM(B52:M52)
A56: HOURLY (1HR) SUMMARY
...

Sheet 11-12AM
A1: 11:00 AM - 12:00 AM
A3: ='7-8AM'!A3:N3
A5: ='7-8AM'!A5:N5
A6: ='7-8AM'!A6:N6
A7: ='7-8AM'!A7:N7
A9: TRAFFIC VOLUME COUNTS DATA (RAW DATA)
A10: 15 MINUTES VOLUMES
A12: TIME | B12: Motorcycle/Tuktuk | C12: Cars(<=5seats) | D12: Large Cars,4WD,SUVs | E12: Pickups/Vans | F12: Minibus/Matatus(<=14seat | G12: Small bus(14-33seat) | H12: Large bus(>33seat) | I12: Light Trucks(2axles) | J12: Medium Trucks(2axle,Double rear wheel) | K12: Heavy Trucks(3, 4 axles) | L12: Artics/draw-bar trucks | M12: Others (e.g tractors) | N12: TOTALS
A13: 11:00-11:15
A14: Mombasa Bound Lane 1 | B14: 23 | C14: 7 | D14: 7 | E14: 1 | F14: 3 | G14: 1 | H14: 0 | I14: 0 | J14: 3 | K14: 3 | L14: 1 | M14: 0 | N14: =SUM(B14:M14)
A15: Mombasa Bound Lane 2 | B15: 10 | C15: 13 | D15: 11 | E15: 3 | F15: 6 | G15: 1 | H15: 0 | I15: 3 | J15: 17 | K15: 8 | L15: 16 | M15: 0 | N15: =SUM(B15:M15)
A16: Mombasa Bound Lane 3 | B16: 2 | C16: 21 | D16: 24 | E16: 11 | F16: 1 | G16: 0 | H16: 0 | I16: 2 | J16: 4 | K16: 3 | L16: 10 | M16: 0 | N16: =SUM(B16:M16)
A17: VEHICLES | B17: =SUM(B14:B16) | C17: =SUM(C14:C16) | D17: =SUM(D14:D16) | E17: =SUM(E14:E16) | F17: =SUM(F14:F16) | G17: =SUM(G14:G16) | H17: =SUM(H14:H16) | I17: =SUM(I14:I16) | ... M17: =SUM(M14:M16) | N17: =SUM(B17:M17)
A18: Conversion Factor | B18: 0.5 | C18: 1 | D18: 1 | E18: 1.75 | F18: 1.75 | G18: 2 | H18: 2.5 | I18: 1.25 | J18: 1.5 | K18: 2.75 | L18: 3 | M18: 2
A19: PCUs, Passenger Car Units | B19: =B17*B18 | C19: =C17*C18 | D19: =D17*D18 | E19: =E17*E18 | F19: =F17*F18 | G19: =G17*G18 | H19: =H17*H18 | I19: =I17*I18 | ... M19: =M17*M18 | N19: =SUM(B19:M19)
A23: TIME | B23: Motorcycle/Tuktuk | C23: Cars(<=5seats) | D23: Large Cars,4WD,SUVs | E23: Pickups/Vans | F23: Minibus/Matatus(<=14seat | G23: Small bus(14-33seat) | H23: Large bus(>33seat) | I23: Light Trucks(2axles) | J23: Medium Trucks(2axle,Double rear wheel) | K23: Heavy Trucks(3, 4 axles) | L23: Artics/draw-bar trucks | M23: Others (e.g tractors) | N23: TOTALS
A24: 11:15-11:30
A25: Mombasa Bound Lane 1 | B25: 15 | C25: 11 | D25: 5 | E25: 2 | F25: 3 | G25: 0 | H25: 0 | I25: 0 | J25: 2 | K25: 2 | L25: 3 | M25: 0 | N25: =SUM(B25:M25)
A26: Mombasa Bound Lane 2 | B26: 9 | C26: 6 | D26: 10 | E26: 5 | F26: 6 | G26: 0 | H26: 0 | I26: 0 | J26: 9 | K26: 12 | L26: 25 | M26: 0 | N26: =SUM(B26:M26)
A27: Mombasa Bound Lane 3 | B27: 2 | C27: 26 | D27: 21 | E27: 7 | F27: 12 | G27: 0 | H27: 0 | I27: 2 | J27: 7 | K27: 3 | L27: 10 | M27: 0 | N27: =SUM(B27:M27)
A28: VEHICLES | B28: =SUM(B25:B27) | C28: =SUM(C25:C27) | D28: =SUM(D25:D27) | E28: =SUM(E25:E27) | F28: =SUM(F25:F27) | G28: =SUM(G25:G27) | H28: =SUM(H25:H27) | I28: =SUM(I25:I27) | ... M28: =SUM(M25:M27) | N28: =SUM(B28:M28)
A29: Conversion Factor | B29: 0.5 | C29: 1 | D29: 1 | E29: 1.75 | F29: 1.75 | G29: 2 | H29: 2.5 | I29: 1.25 | J29: 1.5 | K29: 2.75 | L29: 3 | M29: 2
A30: PCUs, Passenger Car Units | B30: =B28*B29 | C30: =C28*C29 | D30: =D28*D29 | E30: =E28*E29 | F30: =F28*F29 | G30: =G28*G29 | H30: =H28*H29 | I30: =I28*I29 | ... M30: =M28*M29 | N30: =SUM(B30:M30)
A34: TIME | B34: Motorcycle/Tuktuk | C34: Cars(<=5seats) | D34: Large Cars,4WD,SUVs | E34: Pickups/Vans | F34: Minibus/Matatus(<=14seat | G34: Small bus(14-33seat) | H34: Large bus(>33seat) | I34: Light Trucks(2axles) | J34: Medium Trucks(2axle,Double rear wheel) | K34: Heavy Trucks(3, 4 axles) | L34: Artics/draw-bar trucks | M34: Others (e.g tractors) | N34: TOTALS
A35: 11:30-11:45
A36: Mombasa Bound Lane 1 | B36: 18 | C36: 7 | D36: 4 | E36: 1 | F36: 2 | G36: 0 | H36: 0 | I36: 0 | J36: 2 | K36: 2 | L36: 0 | M36: 0 | N36: =SUM(B36:M36)
A37: Mombasa Bound Lane 2 | B37: 6 | C37: 6 | D37: 9 | E37: 5 | F37: 2 | G37: 1 | H37: 0 | I37: 0 | J37: 9 | K37: 8 | L37: 10 | M37: 0 | N37: =SUM(B37:M37)
A38: Mombasa Bound Lane 3 | B38: 2 | C38: 23 | D38: 25 | E38: 4 | F38: 3 | G38: 0 | H38: 1 | I38: 2 | J38: 9 | K38: 5 | L38: 8 | M38: 0 | N38: =SUM(B38:M38)
A39: VEHICLES | B39: =SUM(B36:B38) | C39: =SUM(C36:C38) | D39: =SUM(D36:D38) | E39: =SUM(E36:E38) | F39: =SUM(F36:F38) | G39: =SUM(G36:G38) | H39: =SUM(H36:H38) | I39: =SUM(I36:I38) | ... M39: =SUM(M36:M38) | N39: =SUM(B39:M39)
A40: Conversion Factor | B40: 0.5 | C40: 1 | D40: 1 | E40: 1.75 | F40: 1.75 | G40: 2 | H40: 2.5 | I40: 1.25 | J40: 1.5 | K40: 2.75 | L40: 3 | M40: 2
A41: PCUs, Passenger Car Units | B41: =B39*B40 | C41: =C39*C40 | D41: =D39*D40 | E41: =E39*E40 | F41: =F39*F40 | G41: =G39*G40 | H41: =H39*H40 | I41: =I39*I40 | ... M41: =M39*M40 | N41: =SUM(B41:M41)
A45: TIME | B45: Motorcycle/Tuktuk | C45: Cars(<=5seats) | D45: Large Cars,4WD,SUVs | E45: Pickups/Vans | F45: Minibus/Matatus(<=14seat | G45: Small bus(14-33seat) | H45: Large bus(>33seat) | I45: Light Trucks(2axles) | J45: Medium Trucks(2axle,Double rear wheel) | K45: Heavy Trucks(3, 4 axles) | L45: Artics/draw-bar trucks | M45: Others (e.g tractors) | N45: TOTALS
A46: 11:45-12:00
A47: Mombasa Bound Lane 1 | B47: 15 | C47: 12 | D47: 8 | E47: 4 | F47: 5 | G47: 0 | H47: 1 | I47: 0 | J47: 3 | K47: 0 | L47: 0 | M47: 0 | N47: =SUM(B47:M47)
A48: Mombasa Bound Lane 2 | B48: 8 | C48: 14 | D48: 9 | E48: 2 | F48: 2 | G48: 3 | H48: 0 | I48: 0 | J48: 14 | K48: 7 | L48: 20 | M48: 0 | N48: =SUM(B48:M48)
A49: Mombasa Bound Lane 3 | B49: 0 | C49: 24 | D49: 21 | E49: 5 | F49: 2 | G49: 0 | H49: 1 | I49: 2 | J49: 2 | K49: 4 | L49: 9 | M49: 0 | N49: =SUM(B49:M49)
A50: VEHICLES | B50: =SUM(B47:B49) | C50: =SUM(C47:C49) | D50: =SUM(D47:D49) | E50: =SUM(E47:E49) | F50: =SUM(F47:F49) | G50: =SUM(G47:G49) | H50: =SUM(H47:H49) | I50: =SUM(I47:I49) | ... M50: =SUM(M47:M49) | N50: =SUM(B50:M50)
A51: Conversion Factor | B51: 0.5 | C51: 1 | D51: 1 | E51: 1.75 | F51: 1.75 | G51: 2 | H51: 2.5 | I51: 1.25 | J51: 1.5 | K51: 2.75 | L51: 3 | M51: 2
A52: PCUs, Passenger Car Units | B52: =B50*B51 | C52: =C50*C51 | D52: =D50*D51 | E52: =E50*E51 | F52: =F50*F51 | G52: =G50*G51 | H52: =H50*H51 | I52: =I50*I51 | ... M52: =M50*M51 | N52: =SUM(B52:M52)
A56: HOURLY (1HR) SUMMARY
...

Sheet 12-1PM
A1: 12:00 AM - 1:00 PM
A3: ='7-8AM'!A3:N3
A5: ='7-8AM'!A5:N5
A6: ='7-8AM'!A6:N6
A7: ='7-8AM'!A7:N7
A9: TRAFFIC VOLUME COUNTS DATA (RAW DATA)
A10: 15 MINUTES VOLUMES
A12: TIME | B12: Motorcycle/Tuktuk | C12: Cars(<=5seats) | D12: Large Cars,4WD,SUVs | E12: Pickups/Vans | F12: Minibus/Matatus(<=14seat | G12: Small bus(14-33seat) | H12: Large bus(>33seat) | I12: Light Trucks(2axles) | J12: Medium Trucks(2axle,Double rear wheel) | K12: Heavy Trucks(3, 4 axles) | L12: Artics/draw-bar trucks | M12: Others (e.g tractors) | N12: TOTALS
A13: 12:00-12:15
A14: Mombasa Bound Lane 1 | B14: 24 | C14: 30 | D14: 11 | E14: 3 | F14: 6 | G14: 1 | H14: 0 | I14: 0 | J14: 2 | K14: 1 | L14: 1 | M14: 0 | N14: =SUM(B14:M14)
A15: Mombasa Bound Lane 2 | B15: 8 | C15: 26 | D15: 19 | E15: 5 | F15: 6 | G15: 1 | H15: 0 | I15: 0 | J15: 14 | K15: 10 | L15: 31 | M15: 0 | N15: =SUM(B15:M15)
A16: Mombasa Bound Lane 3 | B16: 1 | C16: 24 | D16: 26 | E16: 9 | F16: 6 | G16: 0 | H16: 0 | I16: 0 | J16: 13 | K16: 2 | L16: 21 | M16: 0 | N16: =SUM(B16:M16)
A17: VEHICLES | B17: =SUM(B14:B16) | C17: =SUM(C14:C16) | D17: =SUM(D14:D16) | E17: =SUM(E14:E16) | F17: =SUM(F14:F16) | G17: =SUM(G14:G16) | H17: =SUM(H14:H16) | I17: =SUM(I14:I16) | ... M17: =SUM(M14:M16) | N17: =SUM(B17:M17)
A18: Conversion Factor | B18: 0.5 | C18: 1 | D18: 1 | E18: 1.75 | F18: 1.75 | G18: 2 | H18: 2.5 | I18: 1.25 | J18: 1.5 | K18: 2.75 | L18: 3 | M18: 2
A19: PCUs, Passenger Car Units | B19: =B17*B18 | C19: =C17*C18 | D19: =D17*D18 | E19: =E17*E18 | F19: =F17*F18 | G19: =G17*G18 | H19: =H17*H18 | I19: =I17*I18 | ... M19: =M17*M18 | N19: =SUM(B19:M19)
A23: TIME | B23: Motorcycle/Tuktuk | C23: Cars(<=5seats) | D23: Large Cars,4WD,SUVs | E23: Pickups/Vans | F23: Minibus/Matatus(<=14seat | G23: Small bus(14-33seat) | H23: Large bus(>33seat) | I23: Light Trucks(2axles) | J23: Medium Trucks(2axle,Double rear wheel) | K23: Heavy Trucks(3, 4 axles) | L23: Artics/draw-bar trucks | M23: Others (e.g tractors) | N23: TOTALS
A24: 12:15-12:30
A25: Mombasa Bound Lane 1 | B25: 22 | C25: 18 | D25: 8 | E25: 3 | F25: 7 | G25: 1 | H25: 0 | I25: 0 | J25: 4 | K25: 1 | L25: 1 | M25: 0 | N25: =SUM(B25:M25)
A26: Mombasa Bound Lane 2 | B26: 10 | C26: 26 | D26: 18 | E26: 8 | F26: 4 | G26: 2 | H26: 0 | I26: 0 | J26: 12 | K26: 8 | L26: 33 | M26: 0 | N26: =SUM(B26:M26)
A27: Mombasa Bound Lane 3 | B27: 2 | C27: 41 | D27: 32 | E27: 7 | F27: 5 | G27: 0 | H27: 0 | I27: 0 | J27: 13 | K27: 3 | L27: 19 | M27: 0 | N27: =SUM(B27:M27)
A28: VEHICLES | B28: =SUM(B25:B27) | C28: =SUM(C25:C27) | D28: =SUM(D25:D27) | E28: =SUM(E25:E27) | F28: =SUM(F25:F27) | G28: =SUM(G25:G27) | H28: =SUM(H25:H27) | I28: =SUM(I25:I27) | ... M28: =SUM(M25:M27) | N28: =SUM(B28:M28)
A29: Conversion Factor | B29: 0.5 | C29: 1 | D29: 1 | E29: 1.75 | F29: 1.75 | G29: 2 | H29: 2.5 | I29: 1.25 | J29: 1.5 | K29: 2.75 | L29: 3 | M29: 2
A30: PCUs, Passenger Car Units | B30: =B28*B29 | C30: =C28*C29 | D30: =D28*D29 | E30: =E28*E29 | F30: =F28*F29 | G30: =G28*G29 | H30: =H28*H29 | I30: =I28*I29 | ... M30: =M28*M29 | N30: =SUM(B30:M30)
A34: TIME | B34: Motorcycle/Tuktuk | C34: Cars(<=5seats) | D34: Large Cars,4WD,SUVs | E34: Pickups/Vans | F34: Minibus/Matatus(<=14seat | G34: Small bus(14-33seat) | H34: Large bus(>33seat) | I34: Light Trucks(2axles) | J34: Medium Trucks(2axle,Double rear wheel) | K34: Heavy Trucks(3, 4 axles) | L34: Artics/draw-bar trucks | M34: Others (e.g tractors) | N34: TOTALS
A35: 12:30-12:45
A36: Mombasa Bound Lane 1 | B36: 28 | C36: 22 | D36: 12 | E36: 3 | F36: 6 | G36: 0 | H36: 0 | I36: 0 | J36: 2 | K36: 1 | L36: 1 | M36: 0 | N36: =SUM(B36:M36)
A37: Mombasa Bound Lane 2 | B37: 9 | C37: 22 | D37: 12 | E37: 7 | F37: 5 | G37: 1 | H37: 0 | I37: 0 | J37: 13 | K37: 7 | L37: 23 | M37: 0 | N37: =SUM(B37:M37)
A38: Mombasa Bound Lane 3 | B38: 1 | C38: 33 | D38: 22 | E38: 8 | F38: 6 | G38: 0 | H38: 0 | I38: 0 | J38: 10 | K38: 2 | L38: 17 | M38: 0 | N38: =SUM(B38:M38)
A39: VEHICLES | B39: =SUM(B36:B38) | C39: =SUM(C36:C38) | D39: =SUM(D36:D38) | E39: =SUM(E36:E38) | F39: =SUM(F36:F38) | G39: =SUM(G36:G38) | H39: =SUM(H36:H38) | I39: =SUM(I36:I38) | ... M39: =SUM(M36:M38) | N39: =SUM(B39:M39)
A40: Conversion Factor | B40: 0.5 | C40: 1 | D40: 1 | E40: 1.75 | F40: 1.75 | G40: 2 | H40: 2.5 | I40: 1.25 | J40: 1.5 | K40: 2.75 | L40: 3 | M40: 2
A41: PCUs, Passenger Car Units | B41: =B39*B40 | C41: =C39*C40 | D41: =D39*D40 | E41: =E39*E40 | F41: =F39*F40 | G41: =G39*G40 | H41: =H39*H40 | I41: =I39*I40 | ... M41: =M39*M40 | N41: =SUM(B41:M41)
A45: TIME | B45: Motorcycle/Tuktuk | C45: Cars(<=5seats) | D45: Large Cars,4WD,SUVs | E45: Pickups/Vans | F45: Minibus/Matatus(<=14seat | G45: Small bus(14-33seat) | H45: Large bus(>33seat) | I45: Light Trucks(2axles) | J45: Medium Trucks(2axle,Double rear wheel) | K45: Heavy Trucks(3, 4 axles) | L45: Artics/draw-bar trucks | M45: Others (e.g tractors) | N45: TOTALS
A46: 12:45-1:00
A47: Mombasa Bound Lane 1 | B47: 38 | C47: 29 | D47: 13 | E47: 4 | F47: 5 | G47: 2 | H47: 2 | I47: 2 | J47: 5 | K47: 1 | L47: 2 | M47: 0 | N47: =SUM(B47:M47)
A48: Mombasa Bound Lane 2 | B48: 18 | C48: 21 | D48: 20 | E48: 7 | F48: 9 | G48: 5 | H48: 3 | I48: 3 | J48: 14 | K48: 14 | L48: 20 | M48: 0 | N48: =SUM(B48:M48)
A49: Mombasa Bound Lane 3 | B49: 5 | C49: 40 | D49: 28 | E49: 16 | F49: 9 | G49: 3 | H49: 2 | I49: 3 | J49: 9 | K49: 9 | L49: 19 | M49: 0 | N49: =SUM(B49:M49)
A50: VEHICLES | B50: =SUM(B47:B49) | C50: =SUM(C47:C49) | D50: =SUM(D47:D49) | E50: =SUM(E47:E49) | F50: =SUM(F47:F49) | G50: =SUM(G47:G49) | H50: =SUM(H47:H49) | I50: =SUM(I47:I49) | ... M50: =SUM(M47:M49) | N50: =SUM(B50:M50)
A51: Conversion Factor | B51: 0.5 | C51: 1 | D51: 1 | E51: 1.75 | F51: 1.75 | G51: 2 | H51: 2.5 | I51: 1.25 | J51: 1.5 | K51: 2.75 | L51: 3 | M51: 2
A52: PCUs, Passenger Car Units | B52: =B50*B51 | C52: =C50*C51 | D52: =D50*D51 | E52: =E50*E51 | F52: =F50*F51 | G52: =G50*G51 | H52: =H50*H51 | I52: =I50*I51 | ... M52: =M50*M51 | N52: =SUM(B52:M52)
A56: HOURLY (1HR) SUMMARY
...

Sheet 1-2PM
A1: 1:00 PM - 2:00 PM
A3: ='7-8AM'!A3:N3
A5: ='7-8AM'!A5:N5
A6: ='7-8AM'!A6:N6
A7: ='7-8AM'!A7:N7
A9: TRAFFIC VOLUME COUNTS DATA (RAW DATA)
A10: 15 MINUTES VOLUMES
A12: TIME | B12: Motorcycle/Tuktuk | C12: Cars(<=5seats) | D12: Large Cars,4WD,SUVs | E12: Pickups/Vans | F12: Minibus/Matatus(<=14seat | G12: Small bus(14-33seat) | H12: Large bus(>33seat) | I12: Light Trucks(2axles) | J12: Medium Trucks(2axle,Double rear wheel) | K12: Heavy Trucks(3, 4 axles) | L12: Artics/draw-bar trucks | M12: Others (e.g tractors) | N12: TOTALS
A13: 1:00-1:15
A14: Mombasa Bound Lane 1 | B14: 28 | C14: 28 | D14: 8 | E14: 3 | F14: 4 | G14: 0 | H14: 0 | I14: 0 | J14: 2 | K14: 0 | L14: 1 | M14: 0 | N14: =SUM(B14:M14)
A15: Mombasa Bound Lane 2 | B15: 12 | C15: 26 | D15: 11 | E15: 8 | F15: 6 | G15: 2 | H15: 0 | I15: 0 | J15: 13 | K15: 8 | L15: 33 | M15: 0 | N15: =SUM(B15:M15)
A16: Mombasa Bound Lane 3 | B16: 2 | C16: 34 | D16: 26 | E16: 11 | F16: 6 | G16: 0 | H16: 0 | I16: 0 | J16: 13 | K16: 4 | L16: 20 | M16: 0 | N16: =SUM(B16:M16)
A17: VEHICLES | B17: =SUM(B14:B16) | C17: =SUM(C14:C16) | D17: =SUM(D14:D16) | E17: =SUM(E14:E16) | F17: =SUM(F14:F16) | G17: =SUM(G14:G16) | H17: =SUM(H14:H16) | I17: =SUM(I14:I16) | ... M17: =SUM(M14:M16) | N17: =SUM(B17:M17)
A18: Conversion Factor | B18: 0.5 | C18: 1 | D18: 1 | E18: 1.75 | F18: 1.75 | G18: 2 | H18: 2.5 | I18: 1.25 | J18: 1.5 | K18: 2.75 | L18: 3 | M18: 2
A19: PCUs, Passenger Car Units | B19: =B17*B18 | C19: =C17*C18 | D19: =D17*D18 | E19: =E17*E18 | F19: =F17*F18 | G19: =G17*G18 | H19: =H17*H18 | I19: =I17*I18 | ... M19: =M17*M18 | N19: =SUM(B19:M19)
A23: TIME | B23: Motorcycle/Tuktuk | C23: Cars(<=5seats) | D23: Large Cars,4WD,SUVs | E23: Pickups/Vans | F23: Minibus/Matatus(<=14seat | G23: Small bus(14-33seat) | H23: Large bus(>33seat) | I23: Light Trucks(2axles) | J23: Medium Trucks(2axle,Double rear wheel) | K23: Heavy Trucks(3, 4 axles) | L23: Artics/draw-bar trucks | M23: Others (e.g tractors) | N23: TOTALS
A24: 1:15-1:30
A25: Mombasa Bound Lane 1 | B25: 22 | C25: 22 | D25: 10 | E25: 3 | F25: 6 | G25: 1 | H25: 0 | I25: 0 | J25: 2 | K25: 0 | L25: 1 | M25: 0 | N25: =SUM(B25:M25)
A26: Mombasa Bound Lane 2 | B26: 15 | C26: 18 | D26: 14 | E26: 4 | F26: 4 | G26: 3 | H26: 0 | I26: 0 | J26: 17 | K26: 11 | L26: 26 | M26: 0 | N26: =SUM(B26:M26)
A27: Mombasa Bound Lane 3 | B27: 1 | C27: 46 | D27: 33 | E27: 7 | F27: 5 | G27: 1 | H27: 0 | I27: 0 | J27: 16 | K27: 3 | L27: 21 | M27: 0 | N27: =SUM(B27:M27)
A28: VEHICLES | B28: =SUM(B25:B27) | C28: =SUM(C25:C27) | D28: =SUM(D25:D27) | E28: =SUM(E25:E27) | F28: =SUM(F25:F27) | G28: =SUM(G25:G27) | H28: =SUM(H25:H27) | I28: =SUM(I25:I27) | ... M28: =SUM(M25:M27) | N28: =SUM(B28:M28)
A29: Conversion Factor | B29: 0.5 | C29: 1 | D29: 1 | E29: 1.75 | F29: 1.75 | G29: 2 | H29: 2.5 | I29: 1.25 | J29: 1.5 | K29: 2.75 | L29: 3 | M29: 2
A30: PCUs, Passenger Car Units | B30: =B28*B29 | C30: =C28*C29 | D30: =D28*D29 | E30: =E28*E29 | F30: =F28*F29 | G30: =G28*G29 | H30: =H28*H29 | I30: =I28*I29 | ... M30: =M28*M29 | N30: =SUM(B30:M30)
A34: TIME | B34: Motorcycle/Tuktuk | C34: Cars(<=5seats) | D34: Large Cars,4WD,SUVs | E34: Pickups/Vans | F34: Minibus/Matatus(<=14seat | G34: Small bus(14-33seat) | H34: Large bus(>33seat) | I34: Light Trucks(2axles) | J34: Medium Trucks(2axle,Double rear wheel) | K34: Heavy Trucks(3, 4 axles) | L34: Artics/draw-bar trucks | M34: Others (e.g tractors) | N34: TOTALS
A35: 1:30-1:45
A36: Mombasa Bound Lane 1 | B36: 25 | C36: 27 | D36: 9 | E36: 3 | F36: 5 | G36: 0 | H36: 0 | I36: 0 | J36: 2 | K36: 1 | L36: 1 | M36: 0 | N36: =SUM(B36:M36)
A37: Mombasa Bound Lane 2 | B37: 15 | C37: 23 | D37: 11 | E37: 5 | F37: 4 | G37: 3 | H37: 0 | I37: 0 | J37: 17 | K37: 5 | L37: 21 | M37: 0 | N37: 66
A38: Mombasa Bound Lane 3 | B38: 2 | C38: 30 | D38: 20 | E38: 7 | F38: 7 | G38: 0 | H38: 0 | I38: 1 | J38: 9 | K38: 4 | L38: 15 | M38: 0 | N38: =SUM(B38:M38)
A39: VEHICLES | B39: =SUM(B36:B38) | C39: =SUM(C36:C38) | D39: =SUM(D36:D38) | E39: =SUM(E36:E38) | F39: =SUM(F36:F38) | G39: =SUM(G36:G38) | H39: =SUM(H36:H38) | I39: =SUM(I36:I38) | ... M39: =SUM(M36:M38) | N39: =SUM(B39:M39)
A40: Conversion Factor | B40: 0.5 | C40: 1 | D40: 1 | E40: 1.75 | F40: 1.75 | G40: 2 | H40: 2.5 | I40: 1.25 | J40: 1.5 | K40: 2.75 | L40: 3 | M40: 2
A41: PCUs, Passenger Car Units | B41: =B39*B40 | C41: =C39*C40 | D41: =D39*D40 | E41: =E39*E40 | F41: =F39*F40 | G41: =G39*G40 | H41: =H39*H40 | I41: =I39*I40 | ... M41: =M39*M40 | N41: =SUM(B41:M41)
A45: TIME | B45: Motorcycle/Tuktuk | C45: Cars(<=5seats) | D45: Large Cars,4WD,SUVs | E45: Pickups/Vans | F45: Minibus/Matatus(<=14seat | G45: Small bus(14-33seat) | H45: Large bus(>33seat) | I45: Light Trucks(2axles) | J45: Medium Trucks(2axle,Double rear wheel) | K45: Heavy Trucks(3, 4 axles) | L45: Artics/draw-bar trucks | M45: Others (e.g tractors) | N45: TOTALS
A46: 1:45-2:00
A47: Mombasa Bound Lane 1 | B47: 28 | C47: 13 | D47: 15 | E47: 6 | F47: 8 | G47: 3 | H47: 1 | I47: 1 | J47: 8 | K47: 3 | L47: 3 | M47: 0 | N47: =SUM(B47:M47)
A48: Mombasa Bound Lane 2 | B48: 7 | C48: 36 | D48: 30 | E48: 9 | F48: 11 | G48: 4 | H48: 3 | I48: 3 | J48: 22 | K48: 10 | L48: 28 | M48: 0 | N48: =SUM(B48:M48)
A49: Mombasa Bound Lane 3 | B49: 5 | C49: 50 | D49: 25 | E49: 14 | F49: 7 | G49: 3 | H49: 2 | I49: 3 | J49: 14 | K49: 5 | L49: 12 | M49: 0 | N49: =SUM(B49:M49)
A50: VEHICLES | B50: =SUM(B47:B49) | C50: =SUM(C47:C49) | D50: =SUM(D47:D49) | E50: =SUM(E47:E49) | F50: =SUM(F47:F49) | G50: =SUM(G47:G49) | H50: =SUM(H47:H49) | I50: =SUM(I47:I49) | ... M50: =SUM(M47:M49) | N50: =SUM(B50:M50)
A51: Conversion Factor | B51: 0.5 | C51: 1 | D51: 1 | E51: 1.75 | F51: 1.75 | G51: 2 | H51: 2.5 | I51: 1.25 | J51: 1.5 | K51: 2.75 | L51: 3 | M51: 2
A52: PCUs, Passenger Car Units | B52: =B50*B51 | C52: =C50*C51 | D52: =D50*D51 | E52: =E50*E51 | F52: =F50*F51 | G52: =G50*G51 | H52: =H50*H51 | I52: =I50*I51 | ... M52: =M50*M51 | N52: =SUM(B52:M52)
A56: HOURLY (1HR) SUMMARY
...

Sheet 2-3PM
A1: 2:00 PM - 3:00 PM
A3: ='7-8AM'!A3:N3
A5: ='7-8AM'!A5:N5
A6: ='7-8AM'!A6:N6
A7: ='7-8AM'!A7:N7
A9: TRAFFIC VOLUME COUNTS DATA (RAW DATA)
A10: 15 MINUTES VOLUMES
A12: TIME | B12: Motorcycle/Tuktuk | C12: Cars(<=5seats) | D12: Large Cars,4WD,SUVs | E12: Pickups/Vans | F12: Minibus/Matatus(<=14seat | G12: Small bus(14-33seat) | H12: Large bus(>33seat) | I12: Light Trucks(2axles) | J12: Medium Trucks(2axle,Double rear wheel) | K12: Heavy Trucks(3, 4 axles) | L12: Artics/draw-bar trucks | M12: Others (e.g tractors) | N12: TOTALS
A13: 2:00-2:15
A14: Mombasa Bound Lane 1 | B14: 21 | C14: 26 | D14: 13 | E14: 2 | F14: 6 | G14: 1 | H14: 0 | I14: 0 | J14: 3 | K14: 0 | L14: 1 | M14: 0 | N14: =SUM(B14:M14)
A15: Mombasa Bound Lane 2 | B15: 11 | C15: 36 | D15: 20 | E15: 6 | F15: 3 | G15: 3 | H15: 0 | I15: 0 | J15: 10 | K15: 9 | L15: 25 | M15: 0 | N15: =SUM(B15:M15)
A16: Mombasa Bound Lane 3 | B16: 2 | C16: 37 | D16: 19 | E16: 11 | F16: 6 | G16: 1 | H16: 0 | I16: 0 | J16: 12 | K16: 5 | L16: 17 | M16: 0 | N16: =SUM(B16:M16)
A17: VEHICLES | B17: =SUM(B14:B16) | C17: =SUM(C14:C16) | D17: =SUM(D14:D16) | E17: =SUM(E14:E16) | F17: =SUM(F14:F16) | G17: =SUM(G14:G16) | H17: =SUM(H14:H16) | I17: =SUM(I14:I16) | ... M17: =SUM(M14:M16) | N17: =SUM(B17:M17)
A18: Conversion Factor | B18: 0.5 | C18: 1 | D18: 1 | E18: 1.75 | F18: 1.75 | G18: 2 | H18: 2.5 | I18: 1.25 | J18: 1.5 | K18: 2.75 | L18: 3 | M18: 2
A19: PCUs, Passenger Car Units | B19: =B17*B18 | C19: =C17*C18 | D19: =D17*D18 | E19: =E17*E18 | F19: =F17*F18 | G19: =G17*G18 | H19: =H17*H18 | I19: =I17*I18 | ... M19: =M17*M18 | N19: =SUM(B19:M19)
A23: TIME | B23: Motorcycle/Tuktuk | C23: Cars(<=5seats) | D23: Large Cars,4WD,SUVs | E23: Pickups/Vans | F23: Minibus/Matatus(<=14seat | G23: Small bus(14-33seat) | H23: Large bus(>33seat) | I23: Light Trucks(2axles) | J23: Medium Trucks(2axle,Double rear wheel) | K23: Heavy Trucks(3, 4 axles) | L23: Artics/draw-bar trucks | M23: Others (e.g tractors) | N23: TOTALS
A24: 2:15-2:30
A25: Mombasa Bound Lane 1 | B25: 24 | C25: 16 | D25: 11 | E25: 3 | F25: 3 | G25: 1 | H25: 0 | I25: 0 | J25: 3 | K25: 0 | L25: 1 | M25: 0 | N25: =SUM(B25:M25)
A26: Mombasa Bound Lane 2 | B26: 8 | C26: 28 | D26: 19 | E26: 7 | F26: 6 | G26: 2 | H26: 0 | I26: 0 | J26: 17 | K26: 11 | L26: 30 | M26: 0 | N26: =SUM(B26:M26)
A27: Mombasa Bound Lane 3 | B27: 1 | C27: 31 | D27: 28 | E27: 8 | F27: 7 | G27: 0 | H27: 0 | I27: 0 | J27: 12 | K27: 2 | L27: 16 | M27: 0 | N27: =SUM(B27:M27)
A28: VEHICLES | B28: =SUM(B25:B27) | C28: =SUM(C25:C27) | D28: =SUM(D25:D27) | E28: =SUM(E25:E27) | F28: =SUM(F25:F27) | G28: =SUM(G25:G27) | H28: =SUM(H25:H27) | I28: =SUM(I25:I27) | ... M28: =SUM(M25:M27) | N28: =SUM(B28:M28)
A29: Conversion Factor | B29: 0.5 | C29: 1 | D29: 1 | E29: 1.75 | F29: 1.75 | G29: 2 | H29: 2.5 | I29: 1.25 | J29: 1.5 | K29: 2.75 | L29: 3 | M29: 2
A30: PCUs, Passenger Car Units | B30: =B28*B29 | C30: =C28*C29 | D30: =D28*D29 | E30: =E28*E29 | F30: =F28*F29 | G30: =G28*G29 | H30: =H28*H29 | I30: =I28*I29 | ... M30: =M28*M29 | N30: =SUM(B30:M30)
A34: TIME | B34: Motorcycle/Tuktuk | C34: Cars(<=5seats) | D34: Large Cars,4WD,SUVs | E34: Pickups/Vans | F34: Minibus/Matatus(<=14seat | G34: Small bus(14-33seat) | H34: Large bus(>33seat) | I34: Light Trucks(2axles) | J34: Medium Trucks(2axle,Double rear wheel) | K34: Heavy Trucks(3, 4 axles) | L34: Artics/draw-bar trucks | M34: Others (e.g tractors) | N34: TOTALS
A35: 2:30-2:45
A36: Mombasa Bound Lane 1 | B36: 23 | C36: 18 | D36: 11 | E36: 2 | F36: 7 | G36: 1 | H36: 0 | I36: 0 | J36: 2 | K36: 0 | L36: 0 | M36: 0 | N36: =SUM(B36:M36)
A37: Mombasa Bound Lane 2 | B37: 8 | C37: 21 | D37: 13 | E37: 5 | F37: 3 | G37: 3 | H37: 0 | I37: 0 | J37: 14 | K37: 6 | L37: 32 | M37: 0 | N37: =SUM(B37:M37)
A38: Mombasa Bound Lane 3 | B38: 2 | C38: 32 | D38: 19 | E38: 10 | F38: 7 | G38: 1 | H38: 0 | I38: 0 | J38: 10 | K38: 4 | L38: 17 | M38: 0 | N38: =SUM(B38:M38)
A39: VEHICLES | B39: =SUM(B36:B38) | C39: =SUM(C36:C38) | D39: =SUM(D36:D38) | E39: =SUM(E36:E38) | F39: =SUM(F36:F38) | G39: =SUM(G36:G38) | H39: =SUM(H36:H38) | I39: =SUM(I36:I38) | ... M39: =SUM(M36:M38) | N39: =SUM(B39:M39)
A40: Conversion Factor | B40: 0.5 | C40: 1 | D40: 1 | E40: 1.75 | F40: 1.75 | G40: 2 | H40: 2.5 | I40: 1.25 | J40: 1.5 | K40: 2.75 | L40: 3 | M40: 2
A41: PCUs, Passenger Car Units | B41: =B39*B40 | C41: =C39*C40 | D41: =D39*D40 | E41: =E39*E40 | F41: =F39*F40 | G41: =G39*G40 | H41: =H39*H40 | I41: =I39*I40 | ... M41: =M39*M40 | N41: =SUM(B41:M41)
A45: TIME | B45: Motorcycle/Tuktuk | C45: Cars(<=5seats) | D45: Large Cars,4WD,SUVs | E45: Pickups/Vans | F45: Minibus/Matatus(<=14seat | G45: Small bus(14-33seat) | H45: Large bus(>33seat) | I45: Light Trucks(2axles) | J45: Medium Trucks(2axle,Double rear wheel) | K45: Heavy Trucks(3, 4 axles) | L45: Artics/draw-bar trucks | M45: Others (e.g tractors) | N45: TOTALS
A46: 2:45-3:00
A47: Mombasa Bound Lane 1 | B47: 31 | C47: 24 | D47: 7 | E47: 7 | F47: 6 | G47: 2 | H47: 1 | I47: 1 | J47: 6 | K47: 3 | L47: 3 | M47: 0 | N47: =SUM(B47:M47)
A48: Mombasa Bound Lane 2 | B48: 15 | C48: 30 | D48: 13 | E48: 12 | F48: 9 | G48: 2 | H48: 3 | I48: 3 | J48: 14 | K48: 9 | L48: 25 | M48: 0 | N48: =SUM(B48:M48)
A49: Mombasa Bound Lane 3 | B49: 5 | C49: 43 | D49: 28 | E49: 11 | F49: 6 | G49: 2 | H49: 2 | I49: 3 | J49: 14 | K49: 6 | L49: 13 | M49: 0 | N49: =SUM(B49:M49)
A50: VEHICLES | B50: =SUM(B47:B49) | C50: =SUM(C47:C49) | D50: =SUM(D47:D49) | E50: =SUM(E47:E49) | F50: =SUM(F47:F49) | G50: =SUM(G47:G49) | H50: =SUM(H47:H49) | I50: =SUM(I47:I49) | ... M50: =SUM(M47:M49) | N50: =SUM(B50:M50)
A51: Conversion Factor | B51: 0.5 | C51: 1 | D51: 1 | E51: 1.75 | F51: 1.75 | G51: 2 | H51: 2.5 | I51: 1.25 | J51: 1.5 | K51: 2.75 | L51: 3 | M51: 2
A52: PCUs, Passenger Car Units | B52: =B50*B51 | C52: =C50*C51 | D52: =D50*D51 | E52: =E50*E51 | F52: =F50*F51 | G52: =G50*G51 | H52: =H50*H51 | I52: =I50*I51 | ... M52: =M50*M51 | N52: =SUM(B52:M52)
A56: HOURLY (1HR) SUMMARY
...

Sheet 3-4PM
A1: 3:00 AM - 4:00 AM
A3: ='7-8AM'!A3:N3
A5: ='7-8AM'!A5:N5
A6: ='7-8AM'!A6:N6
A7: ='7-8AM'!A7:N7
A9: TRAFFIC VOLUME COUNTS DATA (RAW DATA)
A10: 15 MINUTES VOLUMES
A12: TIME | B12: Motorcycle/Tuktuk | C12: Cars(<=5seats) | D12: Large Cars,4WD,SUVs | E12: Pickups/Vans | F12: Minibus/Matatus(<=14seat | G12: Small bus(14-33seat) | H12: Large bus(>33seat) | I12: Light Trucks(2axles) | J12: Medium Trucks(2axle,Double rear wheel) | K12: Heavy Trucks(3, 4 axles) | L12: Artics/draw-bar trucks | M12: Others (e.g tractors) | N12: TOTALS
A13: 3:00-3:15
A14: Mombasa Bound Lane 1 | B14: 18 | C14: 24 | D14: 10 | E14: 3 | F14: 7 | G14: 0 | H14: 0 | I14: 0 | J14: 2 | K14: 0 | L14: 0 | M14: 0 | N14: =SUM(B14:M14)
A15: Mombasa Bound Lane 2 | B15: 8 | C15: 35 | D15: 15 | E15: 5 | F15: 7 | G15: 1 | H15: 0 | I15: 0 | J15: 20 | K15: 11 | L15: 27 | M15: 0 | N15: =SUM(B15:M15)
A16: Mombasa Bound Lane 3 | B16: 1 | C16: 35 | D16: 26 | E16: 11 | F16: 9 | G16: 0 | H16: 0 | I16: 0 | J16: 11 | K16: 3 | L16: 15 | M16: 0 | N16: =SUM(B16:M16)
A17: VEHICLES | B17: =SUM(B14:B16) | C17: =SUM(C14:C16) | D17: =SUM(D14:D16) | E17: =SUM(E14:E16) | F17: =SUM(F14:F16) | G17: =SUM(G14:G16) | H17: =SUM(H14:H16) | I17: =SUM(I14:I16) | ... M17: =SUM(M14:M16) | N17: =SUM(B17:M17)
A18: Conversion Factor | B18: 0.5 | C18: 1 | D18: 1 | E18: 1.75 | F18: 1.75 | G18: 2 | H18: 2.5 | I18: 1.25 | J18: 1.5 | K18: 2.75 | L18: 3 | M18: 2
A19: PCUs, Passenger Car Units | B19: =B17*B18 | C19: =C17*C18 | D19: =D17*D18 | E19: =E17*E18 | F19: =F17*F18 | G19: =G17*G18 | H19: =H17*H18 | I19: =I17*I18 | ... M19: =M17*M18 | N19: =SUM(B19:M19)
A23: TIME | B23: Motorcycle/Tuktuk | C23: Cars(<=5seats) | D23: Large Cars,4WD,SUVs | E23: Pickups/Vans | F23: Minibus/Matatus(<=14seat | G23: Small bus(14-33seat) | H23: Large bus(>33seat) | I23: Light Trucks(2axles) | J23: Medium Trucks(2axle,Double rear wheel) | K23: Heavy Trucks(3, 4 axles) | L23: Artics/draw-bar trucks | M23: Others (e.g tractors) | N23: TOTALS
A24: 3:15-3:30
A25: Mombasa Bound Lane 1 | B25: 30 | C25: 18 | D25: 11 | E25: 3 | F25: 4 | G25: 0 | H25: 0 | I25: 0 | J25: 2 | K25: 0 | L25: 1 | M25: 0 | N25: =SUM(B25:M25)
A26: Mombasa Bound Lane 2 | B26: 9 | C26: 33 | D26: 18 | E26: 8 | F26: 5 | G26: 2 | H26: 0 | I26: 0 | J26: 13 | K26: 8 | L26: 27 | M26: 0 | N26: =SUM(B26:M26)
A27: Mombasa Bound Lane 3 | B27: 2 | C27: 42 | D27: 20 | E27: 9 | F27: 6 | G27: 0 | H27: 0 | I27: 0 | J27: 11 | K27: 5 | L27: 18 | M27: 0 | N27: =SUM(B27:M27)
A28: VEHICLES | B28: =SUM(B25:B27) | C28: =SUM(C25:C27) | D28: =SUM(D25:D27) | E28: =SUM(E25:E27) | F28: =SUM(F25:F27) | G28: =SUM(G25:G27) | H28: =SUM(H25:H27) | I28: =SUM(I25:I27) | ... M28: =SUM(M25:M27) | N28: =SUM(B28:M28)
A29: Conversion Factor | B29: 0.5 | C29: 1 | D29: 1 | E29: 1.75 | F29: 1.75 | G29: 2 | H29: 2.5 | I29: 1.25 | J29: 1.5 | K29: 2.75 | L29: 3 | M29: 2
A30: PCUs, Passenger Car Units | B30: =B28*B29 | C30: =C28*C29 | D30: =D28*D29 | E30: =E28*E29 | F30: =F28*F29 | G30: =G28*G29 | H30: =H28*H29 | I30: =I28*I29 | ... M30: =M28*M29 | N30: =SUM(B30:M30)
A34: TIME | B34: Motorcycle/Tuktuk | C34: Cars(<=5seats) | D34: Large Cars,4WD,SUVs | E34: Pickups/Vans | F34: Minibus/Matatus(<=14seat | G34: Small bus(14-33seat) | H34: Large bus(>33seat) | I34: Light Trucks(2axles) | J34: Medium Trucks(2axle,Double rear wheel) | K34: Heavy Trucks(3, 4 axles) | L34: Artics/draw-bar trucks | M34: Others (e.g tractors) | N34: TOTALS
A35: 3:30-3:45
A36: Mombasa Bound Lane 1 | B36: 32 | C36: 21 | D36: 8 | E36: 4 | F36: 4 | G36: 0 | H36: 0 | I36: 0 | J36: 3 | K36: 0 | L36: 1 | M36: 0 | N36: =SUM(B36:M36)
A37: Mombasa Bound Lane 2 | B37: 13 | C37: 23 | D37: 19 | E37: 6 | F37: 7 | G37: 2 | H37: 0 | I37: 0 | J37: 15 | K37: 11 | L37: 21 | M37: 0 | N37: =SUM(B37:M37)
A38: Mombasa Bound Lane 3 | B38: 2 | C38: 29 | D38: 32 | E38: 7 | F38: 8 | G38: 1 | H38: 0 | I38: 0 | J38: 11 | K38: 4 | L38: 17 | M38: 0 | N38: =SUM(B38:M38)
A39: VEHICLES | B39: =SUM(B36:B38) | C39: =SUM(C36:C38) | D39: =SUM(D36:D38) | E39: =SUM(E36:E38) | F39: =SUM(F36:F38) | G39: =SUM(G36:G38) | H39: =SUM(H36:H38) | I39: =SUM(I36:I38) | ... M39: =SUM(M36:M38) | N39: =SUM(B39:M39)
A40: Conversion Factor | B40: 0.5 | C40: 1 | D40: 1 | E40: 1.75 | F40: 1.75 | G40: 2 | H40: 2.5 | I40: 1.25 | J40: 1.5 | K40: 2.75 | L40: 3 | M40: 2
A41: PCUs, Passenger Car Units | B41: =B39*B40 | C41: =C39*C40 | D41: =D39*D40 | E41: =E39*E40 | F41: =F39*F40 | G41: =G39*G40 | H41: =H39*H40 | I41: =I39*I40 | ... M41: =M39*M40 | N41: =SUM(B41:M41)
A45: TIME | B45: Motorcycle/Tuktuk | C45: Cars(<=5seats) | D45: Large Cars,4WD,SUVs | E45: Pickups/Vans | F45: Minibus/Matatus(<=14seat | G45: Small bus(14-33seat) | H45: Large bus(>33seat) | I45: Light Trucks(2axles) | J45: Medium Trucks(2axle,Double rear wheel) | K45: Heavy Trucks(3, 4 axles) | L45: Artics/draw-bar trucks | M45: Others (e.g tractors) | N45: TOTALS
A46: 3:45-4:00
A47: Mombasa Bound Lane 1 | B47: 23 | C47: 15 | D47: 17 | E47: 6 | F47: 8 | G47: 3 | H47: 1 | I47: 1 | J47: 6 | K47: 4 | L47: 3 | M47: 0 | N47: =SUM(B47:M47)
A48: Mombasa Bound Lane 2 | B48: 17 | C48: 22 | D48: 15 | E48: 8 | F48: 6 | G48: 4 | H48: 3 | I48: 3 | J48: 21 | K48: 8 | L48: 33 | M48: 0 | N48: =SUM(B48:M48)
A49: Mombasa Bound Lane 3 | B49: 5 | C49: 48 | D49: 27 | E49: 15 | F49: 9 | G49: 3 | H49: 2 | I49: 3 | J49: 24 | K49: 5 | L49: 8 | M49: 0 | N49: =SUM(B49:M49)
A50: VEHICLES | B50: =SUM(B47:B49) | C50: =SUM(C47:C49) | D50: =SUM(D47:D49) | E50: =SUM(E47:E49) | F50: =SUM(F47:F49) | G50: =SUM(G47:G49) | H50: =SUM(H47:H49) | I50: =SUM(I47:I49) | ... M50: =SUM(M47:M49) | N50: =SUM(B50:M50)
A51: Conversion Factor | B51: 0.5 | C51: 1 | D51: 1 | E51: 1.75 | F51: 1.75 | G51: 2 | H51: 2.5 | I51: 1.25 | J51: 1.5 | K51: 2.75 | L51: 3 | M51: 2
A52: PCUs, Passenger Car Units | B52: =B50*B51 | C52: =C50*C51 | D52: =D50*D51 | E52: =E50*E51 | F52: =F50*F51 | G52: =G50*G51 | H52: =H50*H51 | I52: =I50*I51 | ... M52: =M50*M51 | N52: =SUM(B52:M52)
A56: HOURLY (1HR) SUMMARY
...

Sheet 4-5PM
A1: 4:00 PM - 5:00 PM
A3: ='7-8AM'!A3:N3
A5: ='7-8AM'!A5:N5
A6: ='7-8AM'!A6:N6
A7: ='7-8AM'!A7:N7
A9: TRAFFIC VOLUME COUNTS DATA (RAW DATA)
A10: 15 MINUTES VOLUMES
A12: TIME | B12: Motorcycle/Tuktuk | C12: Cars(<=5seats) | D12: Large Cars,4WD,SUVs | E12: Pickups/Vans | F12: Minibus/Matatus(<=14seat | G12: Small bus(14-33seat) | H12: Large bus(>33seat) | I12: Light Trucks(2axles) | J12: Medium Trucks(2axle,Double rear wheel) | K12: Heavy Trucks(3, 4 axles) | L12: Artics/draw-bar trucks | M12: Others (e.g tractors) | N12: TOTALS
A13: 4:00-4:15
A14: Mombasa Bound Lane 1 | B14: 31 | C14: 29 | D14: 16 | E14: 4 | F14: 7 | G14: 1 | H14: 0 | I14: 0 | J14: 3 | K14: 0 | L14: 0 | M14: 0 | N14: =SUM(B14:M14)
A15: Mombasa Bound Lane 2 | B15: 15 | C15: 25 | D15: 17 | E15: 8 | F15: 8 | G15: 2 | H15: 0 | I15: 0 | J15: 13 | K15: 11 | L15: 32 | M15: 0 | N15: =SUM(B15:M15)
A16: Mombasa Bound Lane 3 | B16: 3 | C16: 46 | D16: 32 | E16: 13 | F16: 8 | G16: 1 | H16: 0 | I16: 1 | J16: 18 | K16: 5 | L16: 26 | M16: 0 | N16: =SUM(B16:M16)
A17: VEHICLES | B17: =SUM(B14:B16) | C17: =SUM(C14:C16) | D17: =SUM(D14:D16) | E17: =SUM(E14:E16) | F17: =SUM(F14:F16) | G17: =SUM(G14:G16) | H17: =SUM(H14:H16) | I17: =SUM(I14:I16) | ... M17: =SUM(M14:M16) | N17: =SUM(B17:M17)
A18: Conversion Factor | B18: 0.5 | C18: 1 | D18: 1 | E18: 1.75 | F18: 1.75 | G18: 2 | H18: 2.5 | I18: 1.25 | J18: 1.5 | K18: 2.75 | L18: 3 | M18: 2
A19: PCUs, Passenger Car Units | B19: =B17*B18 | C19: =C17*C18 | D19: =D17*D18 | E19: =E17*E18 | F19: =F17*F18 | G19: =G17*G18 | H19: =H17*H18 | I19: =I17*I18 | ... M19: =M17*M18 | N19: =SUM(B19:M19)
A23: TIME | B23: Motorcycle/Tuktuk | C23: Cars(<=5seats) | D23: Large Cars,4WD,SUVs | E23: Pickups/Vans | F23: Minibus/Matatus(<=14seat | G23: Small bus(14-33seat) | H23: Large bus(>33seat) | I23: Light Trucks(2axles) | J23: Medium Trucks(2axle,Double rear wheel) | K23: Heavy Trucks(3, 4 axles) | L23: Artics/draw-bar trucks | M23: Others (e.g tractors) | N23: TOTALS
A24: 4:15-4:30
A25: Mombasa Bound Lane 1 | B25: 37 | C25: 25 | D25: 9 | E25: 3 | F25: 6 | G25: 1 | H25: 0 | I25: 0 | J25: 4 | K25: 0 | L25: 0 | M25: 0 | N25: =SUM(B25:M25)
A26: Mombasa Bound Lane 2 | B26: 11 | C26: 38 | D26: 26 | E26: 5 | F26: 10 | G26: 3 | H26: 0 | I26: 0 | J26: 13 | K26: 14 | L26: 40 | M26: 0 | N26: =SUM(B26:M26)
A27: Mombasa Bound Lane 3 | B27: 2 | C27: 40 | D27: 29 | E27: 8 | F27: 7 | G27: 0 | H27: 0 | I27: 1 | J27: 13 | K27: 5 | L27: 24 | M27: 0 | N27: =SUM(B27:M27)
A28: VEHICLES | B28: =SUM(B25:B27) | C28: =SUM(C25:C27) | D28: =SUM(D25:D27) | E28: =SUM(E25:E27) | F28: =SUM(F25:F27) | G28: =SUM(G25:G27) | H28: =SUM(H25:H27) | I28: =SUM(I25:I27) | ... M28: =SUM(M25:M27) | N28: =SUM(B28:M28)
A29: Conversion Factor | B29: 0.5 | C29: 1 | D29: 1 | E29: 1.75 | F29: 1.75 | G29: 2 | H29: 2.5 | I29: 1.25 | J29: 1.5 | K29: 2.75 | L29: 3 | M29: 2
A30: PCUs, Passenger Car Units | B30: =B28*B29 | C30: =C28*C29 | D30: =D28*D29 | E30: =E28*E29 | F30: =F28*F29 | G30: =G28*G29 | H30: =H28*H29 | I30: =I28*I29 | ... M30: =M28*M29 | N30: =SUM(B30:M30)
A34: TIME | B34: Motorcycle/Tuktuk | C34: Cars(<=5seats) | D34: Large Cars,4WD,SUVs | E34: Pickups/Vans | F34: Minibus/Matatus(<=14seat | G34: Small bus(14-33seat) | H34: Large bus(>33seat) | I34: Light Trucks(2axles) | J34: Medium Trucks(2axle,Double rear wheel) | K34: Heavy Trucks(3, 4 axles) | L34: Artics/draw-bar trucks | M34: Others (e.g tractors) | N34: TOTALS
A35: 4:30-4:45
A36: Mombasa Bound Lane 1 | B36: 27 | C36: 20 | D36: 10 | E36: 3 | F36: 8 | G36: 1 | H36: 0 | I36: 0 | J36: 4 | K36: 0 | L36: 1 | M36: 0 | N36: =SUM(B36:M36)
A37: Mombasa Bound Lane 2 | B37: 10 | C37: 37 | D37: 24 | E37: 9 | F37: 7 | G37: 3 | H37: 0 | I37: 0 | J37: 14 | K37: 9 | L37: 31 | M37: 0 | N37: =SUM(B37:M37)
A38: Mombasa Bound Lane 3 | B38: 4 | C38: 34 | D38: 37 | E38: 13 | F38: 8 | G38: 1 | H38: 0 | I38: 1 | J38: 19 | K38: 4 | L38: 15 | M38: 0 | N38: =SUM(B38:M38)
A39: VEHICLES | B39: =SUM(B36:B38) | C39: =SUM(C36:C38) | D39: =SUM(D36:D38) | E39: =SUM(E36:E38) | F39: =SUM(F36:F38) | G39: =SUM(G36:G38) | H39: =SUM(H36:H38) | I39: =SUM(I36:I38) | ... M39: =SUM(M36:M38) | N39: =SUM(B39:M39)
A40: Conversion Factor | B40: 0.5 | C40: 1 | D40: 1 | E40: 1.75 | F40: 1.75 | G40: 2 | H40: 2.5 | I40: 1.25 | J40: 1.5 | K40: 2.75 | L40: 3 | M40: 2
A41: PCUs, Passenger Car Units | B41: =B39*B40 | C41: =C39*C40 | D41: =D39*D40 | E41: =E39*E40 | F41: =F39*F40 | G41: =G39*G40 | H41: =H39*H40 | I41: =I39*I40 | ... M41: =M39*M40 | N41: =SUM(B41:M41)
A45: TIME | B45: Motorcycle/Tuktuk | C45: Cars(<=5seats) | D45: Large Cars,4WD,SUVs | E45: Pickups/Vans | F45: Minibus/Matatus(<=14seat | G45: Small bus(14-33seat) | H45: Large bus(>33seat) | I45: Light Trucks(2axles) | J45: Medium Trucks(2axle,Double rear wheel) | K45: Heavy Trucks(3, 4 axles) | L45: Artics/draw-bar trucks | M45: Others (e.g tractors) | N45: TOTALS
A46: 4:45-5:00
A47: Mombasa Bound Lane 1 | B47: 46 | C47: 25 | D47: 17 | E47: 6 | F47: 7 | G47: 1 | H47: 1 | I47: 1 | J47: 5 | K47: 3 | L47: 3 | M47: 0 | N47: =SUM(B47:M47)
A48: Mombasa Bound Lane 2 | B48: 14 | C48: 22 | D48: 22 | E48: 10 | F48: 6 | G48: 5 | H48: 4 | I48: 2 | J48: 26 | K48: 12 | L48: 32 | M48: 0 | N48: =SUM(B48:M48)
A49: Mombasa Bound Lane 3 | B49: 4 | C49: 45 | D49: 29 | E49: 9 | F49: 15 | G49: 2 | H49: 2 | I49: 1 | J49: 18 | K49: 5 | L49: 21 | M49: 0 | N49: =SUM(B49:M49)
A50: VEHICLES | B50: =SUM(B47:B49) | C50: =SUM(C47:C49) | D50: =SUM(D47:D49) | E50: =SUM(E47:E49) | F50: =SUM(F47:F49) | G50: =SUM(G47:G49) | H50: =SUM(H47:H49) | I50: =SUM(I47:I49) | ... M50: =SUM(M47:M49) | N50: =SUM(B50:M50)
A51: Conversion Factor | B51: 0.5 | C51: 1 | D51: 1 | E51: 1.75 | F51: 1.75 | G51: 2 | H51: 2.5 | I51: 1.25 | J51: 1.5 | K51: 2.75 | L51: 3 | M51: 2
A52: PCUs, Passenger Car Units | B52: =B50*B51 | C52: =C50*C51 | D52: =D50*D51 | E52: =E50*E51 | F52: =F50*F51 | G52: =G50*G51 | H52: =H50*H51 | I52: =I50*I51 | ... M52: =M50*M51 | N52: =SUM(B52:M52)
A56: HOURLY (1HR) SUMMARY
...

Sheet 5-6PM 
A1: 5:00 PM - 6:00 PM
A3: ='7-8AM'!A3:N3
A5: ='7-8AM'!A5:N5
A6: ='7-8AM'!A6:N6
A7: ='7-8AM'!A7:N7
A9: TRAFFIC VOLUME COUNTS DATA (RAW DATA)
A10: 15 MINUTES VOLUMES
