Workbook

Sheet 7-8AM
A1: 07:00 AM - 08:00 AM
A3: ROAD: JN A8 MAILI TISA-KITALE (B14) ROAD
A5: SITE: JN A8 MAILI TISA-KITALE (B14) ROAD
A6: PROJECT: PROPOSED FUEL SERVICE STATION
A7: C/O: GIDEON KAGO KARIUKI
A9: TRAFFIC VOLUME COUNTS DATA (RAW DATA)
A10: 15 MINUTES VOLUMES
A12: TIME | B12: Motorcycle/Tuktuk | C12: Cars(<=5seats) | D12: Large Cars,4WD,SUVs | E12: Large Cars,4WD,SUVs | F12: Minibus/Matatus(<=14seat | G12: Small bus(14-33seat) | H12: Large bus(>33seat) | I12: Light Trucks(2axles) | J12: Medium Trucks(2axle,Double rear wheel) | K12: Heavy Trucks(3, 4 axles) | L12: Artics/draw-bar trucks | M12: Others (e.g tractors) | N12: TOTALS
A13: 7:00-7:15
A14: Maili Tisa Bound | B14: 7 | C14: 10 | D14: 10 | E14: 10 | F14: 6 | G14: 0 | H14: 1 | I14: 1 | J14: 1 | K14: 1 | L14: 0 | M14: 0 | N14: =SUM(B14:M14) -> 47
A15: Kitale Bound | B15: 13 | C15: 16 | D15: 7 | E15: 1 | F15: 4 | G15: 0 | H15: 0 | I15: 0 | J15: 1 | K15: 0 | L15: 0 | M15: 0 | N15: =SUM(B15:M15) -> 42
A16: VEHICLES | B16: =SUM(B14:B15) -> 20 | C16: =SUM(C14:C15) -> 26 | D16: =SUM(D14:D15) -> 17 | E16: =SUM(E14:E15) -> 11 | F16: =SUM(F14:F15) -> 10 | G16: =SUM(G14:G15) -> 0 | H16: =SUM(H14:H15) -> 1 | I16: =SUM(I14:I15) -> 1 | ... M16: =SUM(M14:M15) -> 0 | N16: =SUM(B16:M16) -> 89
A17: Conversion Factor | B17: 0 | C17: 1 | D17: 1 | E17: 1 | F17: 1 | G17: 1 | H17: 2 | I17: 1 | J17: 1 | K17: 2 | L17: 2 | M17: 1
A18: PCUs, Passenger Car Units | B18: =B16*B17 -> 0 | C18: =C16*C17 -> 26 | D18: =D16*D17 -> 17 | E18: =E16*E17 -> 11 | F18: =F16*F17 -> 10 | G18: =G16*G17 -> 0 | H18: =H16*H17 -> 2 | I18: =I16*I17 -> 1 | ... M18: =M16*M17 -> 0 | N18: =SUM(B18:M18) -> 71
A22: TIME | B22: Motorcycle/Tuktuk | C22: Cars(<=5seats) | D22: Large Cars,4WD,SUVs | E22: Pickups/Vans | F22: Minibus/Matatus(<=14seat | G22: Small bus(14-33seat) | H22: Large bus(>33seat) | I22: Light Trucks(2axles) | J22: Medium Trucks(2axle,Double rear wheel) | K22: Heavy Trucks(3, 4 axles) | L22: Artics/draw-bar trucks | M22: Others (e.g tractors) | N22: TOTALS
A23: 7:15-7:30
A24: Maili Tisa Bound | B24: 15 | C24: 8 | D24: 9 | E24: 11 | F24: 7 | G24: 0 | H24: 1 | I24: 3 | J24: 1 | K24: 0 | L24: 0 | M24: 0 | N24: =SUM(B24:M24) -> 55
A25: Kitale Bound | B25: 13 | C25: 12 | D25: 18 | E25: 4 | F25: 6 | G25: 0 | H25: 0 | I25: 2 | J25: 1 | K25: 1 | L25: 0 | M25: 0 | N25: =SUM(B25:M25) -> 57
A26: VEHICLES | B26: =SUM(B24:B25) -> 28 | C26: =SUM(C24:C25) -> 20 | D26: =SUM(D24:D25) -> 27 | E26: =SUM(E24:E25) -> 15 | F26: =SUM(F24:F25) -> 13 | G26: =SUM(G24:G25) -> 0 | H26: =SUM(H24:H25) -> 1 | I26: =SUM(I24:I25) -> 5 | ... M26: =SUM(M24:M25) -> 0 | N26: =SUM(B26:M26) -> 112
A27: Conversion Factor | B27: 0 | C27: 1 | D27: 1 | E27: 1 | F27: 1 | G27: 1 | H27: 2 | I27: 1 | J27: 1 | K27: 2 | L27: 2 | M27: 1
A28: PCUs, Passenger Car Units | B28: =B26*B27 -> 0 | C28: =C26*C27 -> 20 | D28: =D26*D27 -> 27 | E28: =E26*E27 -> 15 | F28: =F26*F27 -> 13 | G28: =G26*G27 -> 0 | H28: =H26*H27 -> 2 | I28: =I26*I27 -> 5 | ... M28: =M26*M27 -> 0 | N28: =SUM(B28:M28) -> 86
A32: TIME | B32: Motorcycle/Tuktuk | C32: Cars(<=5seats) | D32: Large Cars,4WD,SUVs | E32: Pickups/Vans | F32: Minibus/Matatus(<=14seat | G32: Small bus(14-33seat) | H32: Large bus(>33seat) | I32: Light Trucks(2axles) | J32: Medium Trucks(2axle,Double rear wheel) | K32: Heavy Trucks(3, 4 axles) | L32: Artics/draw-bar trucks | M32: Others (e.g tractors) | N32: TOTALS
A33: 7:30-7:45
A34: Maili Tisa Bound | B34: 14 | C34: 22 | D34: 15 | E34: 3 | F34: 4 | G34: 0 | H34: 1 | I34: 0 | J34: 3 | K34: 0 | L34: 0 | M34: 0 | N34: =SUM(B34:M34) -> 62
A35: Kitale Bound | B35: 11 | C35: 22 | D35: 4 | E35: 7 | F35: 6 | G35: 0 | H35: 6 | I35: 2 | J35: 1 | K35: 1 | L35: 0 | M35: 0 | N35: =SUM(B35:M35) -> 60
A36: VEHICLES | B36: =SUM(B34:B35) -> 25 | C36: =SUM(C34:C35) -> 44 | D36: =SUM(D34:D35) -> 19 | E36: =SUM(E34:E35) -> 10 | F36: =SUM(F34:F35) -> 10 | G36: =SUM(G34:G35) -> 0 | H36: =SUM(H34:H35) -> 7 | I36: =SUM(I34:I35) -> 2 | ... M36: =SUM(M34:M35) -> 0 | N36: =SUM(B36:M36) -> 122
A37: Conversion Factor | B37: 0 | C37: 1 | D37: 1 | E37: 1 | F37: 1 | G37: 1 | H37: 2 | I37: 1 | J37: 1 | K37: 2 | L37: 2 | M37: 1
A38: PCUs, Passenger Car Units | B38: =B36*B37 -> 0 | C38: =C36*C37 -> 44 | D38: =D36*D37 -> 19 | E38: =E36*E37 -> 10 | F38: =F36*F37 -> 10 | G38: =G36*G37 -> 0 | H38: =H36*H37 -> 14 | I38: =I36*I37 -> 2 | ... M38: =M36*M37 -> 0 | N38: =SUM(B38:M38) -> 105
A42: TIME | B42: Motorcycle/Tuktuk | C42: Cars(<=5seats) | D42: Large Cars,4WD,SUVs | E42: Pickups/Vans | F42: Minibus/Matatus(<=14seat | G42: Small bus(14-33seat) | H42: Large bus(>33seat) | I42: Light Trucks(2axles) | J42: Medium Trucks(2axle,Double rear wheel) | K42: Heavy Trucks(3, 4 axles) | L42: Artics/draw-bar trucks | M42: Others (e.g tractors) | N42: TOTALS
A43: 7:45-8:00
A44: Maili Tisa Bound | B44: 15 | C44: 15 | D44: 10 | E44: 4 | F44: 4 | G44: 1 | H44: 0 | I44: 0 | J44: 0 | K44: 2 | L44: 1 | M44: 0 | N44: =SUM(B44:M44) -> 52
A45: Kitale Bound | B45: 9 | C45: 24 | D45: 3 | E45: 6 | F45: 9 | G45: 0 | H45: 0 | I45: 0 | J45: 1 | K45: 1 | L45: 0 | M45: 0 | N45: =SUM(B45:M45) -> 53
A46: VEHICLES | B46: =SUM(B44:B45) -> 24 | C46: =SUM(C44:C45) -> 39 | D46: =SUM(D44:D45) -> 13 | E46: =SUM(E44:E45) -> 10 | F46: =SUM(F44:F45) -> 13 | G46: =SUM(G44:G45) -> 1 | H46: =SUM(H44:H45) -> 0 | I46: =SUM(I44:I45) -> 0 | ... M46: =SUM(M44:M45) -> 0 | N46: =SUM(B46:M46) -> 105
A47: Conversion Factor | B47: 0 | C47: 1 | D47: 1 | E47: 1 | F47: 1 | G47: 1 | H47: 2 | I47: 1 | J47: 1 | K47: 2 | L47: 2 | M47: 1
A48: PCUs, Passenger Car Units | B48: =B46*B47 -> 0 | C48: =C46*C47 -> 39 | D48: =D46*D47 -> 13 | E48: =E46*E47 -> 10 | F48: =F46*F47 -> 13 | G48: =G46*G47 -> 1 | H48: =H46*H47 -> 0 | I48: =I46*I47 -> 0 | ... M48: =M46*M47 -> 0 | N48: =SUM(B48:M48) -> 85
A52: HOURLY (1HR) SUMMARY
A54: TIME | B54: Motorcycle/Tuktuk | C54: Cars(<=5seats) | D54: Large Cars,4WD,SUVs | E54: Pickups/Vans | F54: Minibus/Matatus(<=14seat | G54: Small bus(14-33seat) | H54: Large bus(>33seat) | I54: Light Trucks(2axles) | J54: Medium Trucks(2axle,Double rear wheel) | K54: Heavy Trucks(3, 4 axles) | L54: Artics/draw-bar trucks | M54: Others (e.g tractors) | N54: TOTALS
A55: 07 AM to 08 AM
A56: Maili Tisa Bound | B56: =(B14+B24+B34+B44) -> 51 | C56: =(C14+C24+C34+C44) -> 55 | D56: =(D14+D24+D34+D44) -> 44 | E56: =(E14+E24+E34+E44) -> 28 | F56: =(F14+F24+F34+F44) -> 21 | G56: =(G14+G24+G34+G44) -> 1 | H56: =(H14+H24+H34+H44) -> 3 | I56: =(I14+I24+I34+I44) -> 4 | ... M56: =(M14+M24+M34+M44) -> 0 | N56: =SUM(B56:M56) -> 216
A57: Kitale Bound | B57: =(B15+B25+B35+B45) -> 46 | C57: =(C15+C25+C35+C45) -> 74 | D57: =(D15+D25+D35+D45) -> 32 | E57: =(E15+E25+E35+E45) -> 18 | F57: =(F15+F25+F35+F45) -> 25 | G57: =(G15+G25+G35+G45) -> 0 | H57: =(H15+H25+H35+H45) -> 6 | I57: =(I15+I25+I35+I45) -> 4 | ... M57: =(M15+M25+M35+M45) -> 0 | N57: =SUM(B57:M57) -> 212
...

Sheet 8-9AM
A1: 08:00 AM - 09:00 AM
A3: ='7-8AM'!A3 -> ROAD: JN A8 MAILI TISA-KITALE (B14) ROAD
A5: ='7-8AM'!A5 -> SITE: JN A8 MAILI TISA-KITALE (B14) ROAD
A6: ='7-8AM'!A6 -> PROJECT: PROPOSED FUEL SERVICE STATION
A7: ='7-8AM'!A7 -> C/O: GIDEON KAGO KARIUKI
A9: TRAFFIC VOLUME COUNTS DATA (RAW DATA)
A10: 15 MINUTES VOLUMES
A12: TIME | B12: Motorcycle/Tuktuk | C12: Cars(<=5seats) | D12: Large Cars,4WD,SUVs | E12: Pickups/Vans | F12: Minibus/Matatus(<=14seat | G12: Small bus(14-33seat) | H12: Large bus(>33seat) | I12: Light Trucks(2axles) | J12: Medium Trucks(2axle,Double rear wheel) | K12: Heavy Trucks(3, 4 axles) | L12: Artics/draw-bar trucks | M12: Others (e.g tractors) | N12: TOTALS
A13: 8:00-8:15
A14: ='7-8AM'!A14 -> Maili Tisa Bound | B14: 16 | C14: 13 | D14: 6 | E14: 7 | F14: 5 | G14: 1 | H14: 1 | I14: 0 | J14: 1 | K14: 1 | L14: 0 | M14: 0 | N14: =SUM(B14:M14) -> 51
A15: ='7-8AM'!A15 -> Kitale Bound | B15: 14 | C15: 16 | D15: 12 | E15: 3 | F15: 7 | G15: 0 | H15: 0 | I15: 0 | J15: 1 | K15: 0 | L15: 1 | M15: 0 | N15: =SUM(B15:M15) -> 54
A16: VEHICLES | B16: =SUM(B14:B15) -> 30 | C16: =SUM(C14:C15) -> 29 | D16: =SUM(D14:D15) -> 18 | E16: =SUM(E14:E15) -> 10 | F16: =SUM(F14:F15) -> 12 | G16: =SUM(G14:G15) -> 1 | H16: =SUM(H14:H15) -> 1 | I16: =SUM(I14:I15) -> 0 | ... M16: =SUM(M14:M15) -> 0 | N16: =SUM(B16:M16) -> 105
A17: Conversion Factor | B17: 0 | C17: 1 | D17: 1 | E17: 1 | F17: 1 | G17: 1 | H17: 2 | I17: 1 | J17: 1 | K17: 2 | L17: 2 | M17: 1
A18: PCUs, Passenger Car Units | B18: =B16*B17 -> 0 | C18: =C16*C17 -> 29 | D18: =D16*D17 -> 18 | E18: =E16*E17 -> 10 | F18: =F16*F17 -> 12 | G18: =G16*G17 -> 1 | H18: =H16*H17 -> 2 | I18: =I16*I17 -> 0 | ... M18: =M16*M17 -> 0 | N18: =SUM(B18:M18) -> 78
A22: TIME | B22: Motorcycle/Tuktuk | C22: Cars(<=5seats) | D22: Large Cars,4WD,SUVs | E22: Pickups/Vans | F22: Minibus/Matatus(<=14seat | G22: Small bus(14-33seat) | H22: Large bus(>33seat) | I22: Light Trucks(2axles) | J22: Medium Trucks(2axle,Double rear wheel) | K22: Heavy Trucks(3, 4 axles) | L22: Artics/draw-bar trucks | M22: Others (e.g tractors) | N22: TOTALS
A23: 8:15-8:30
A24: ='7-8AM'!A24 -> Maili Tisa Bound | B24: 15 | C24: 16 | D24: 7 | E24: 6 | F24: 7 | G24: 2 | H24: 0 | I24: 1 | J24: 1 | K24: 1 | L24: 0 | M24: 0 | N24: =SUM(B24:M24) -> 56
A25: ='7-8AM'!A25 -> Kitale Bound | B25: 15 | C25: 11 | D25: 11 | E25: 3 | F25: 4 | G25: 0 | H25: 1 | I25: 0 | J25: 1 | K25: 0 | L25: 0 | M25: 0 | N25: =SUM(B25:M25) -> 46
A26: VEHICLES | B26: =SUM(B24:B25) -> 30 | C26: =SUM(C24:C25) -> 27 | D26: =SUM(D24:D25) -> 18 | E26: =SUM(E24:E25) -> 9 | F26: =SUM(F24:F25) -> 11 | G26: =SUM(G24:G25) -> 2 | H26: =SUM(H24:H25) -> 1 | I26: =SUM(I24:I25) -> 1 | ... M26: =SUM(M24:M25) -> 0 | N26: =SUM(B26:M26) -> 102
A27: Conversion Factor | B27: 0 | C27: 1 | D27: 1 | E27: 1 | F27: 1 | G27: 1 | H27: 2 | I27: 1 | J27: 1 | K27: 2 | L27: 2 | M27: 1
A28: PCUs, Passenger Car Units | B28: =B26*B27 -> 0 | C28: =C26*C27 -> 27 | D28: =D26*D27 -> 18 | E28: =E26*E27 -> 9 | F28: =F26*F27 -> 11 | G28: =G26*G27 -> 2 | H28: =H26*H27 -> 2 | I28: =I26*I27 -> 1 | ... M28: =M26*M27 -> 0 | N28: =SUM(B28:M28) -> 74
A32: TIME | B32: Motorcycle/Tuktuk | C32: Cars(<=5seats) | D32: Large Cars,4WD,SUVs | E32: Pickups/Vans | F32: Minibus/Matatus(<=14seat | G32: Small bus(14-33seat) | H32: Large bus(>33seat) | I32: Light Trucks(2axles) | J32: Medium Trucks(2axle,Double rear wheel) | K32: Heavy Trucks(3, 4 axles) | L32: Artics/draw-bar trucks | M32: Others (e.g tractors) | N32: TOTALS
A33: 8:30-8:45
A34: ='7-8AM'!A34 -> Maili Tisa Bound | B34: 16 | C34: 13 | D34: 5 | E34: 2 | F34: 5 | G34: 3 | H34: 1 | I34: 4 | J34: 2 | K34: 1 | L34: 0 | M34: 0 | N34: =SUM(B34:M34) -> 52
A35: ='7-8AM'!A35 -> Kitale Bound | B35: 11 | C35: 8 | D35: 11 | E35: 4 | F35: 8 | G35: 1 | H35: 0 | I35: 0 | J35: 1 | K35: 0 | L35: 0 | M35: 0 | N35: =SUM(B35:M35) -> 44
A36: VEHICLES | B36: =SUM(B34:B35) -> 27 | C36: =SUM(C34:C35) -> 21 | D36: =SUM(D34:D35) -> 16 | E36: =SUM(E34:E35) -> 6 | F36: =SUM(F34:F35) -> 13 | G36: =SUM(G34:G35) -> 4 | H36: =SUM(H34:H35) -> 1 | I36: =SUM(I34:I35) -> 4 | ... M36: =SUM(M34:M35) -> 0 | N36: =SUM(B36:M36) -> 96
A37: Conversion Factor | B37: 0 | C37: 1 | D37: 1 | E37: 1 | F37: 1 | G37: 1 | H37: 2 | I37: 1 | J37: 1 | K37: 2 | L37: 2 | M37: 1
A38: PCUs, Passenger Car Units | B38: =B36*B37 -> 0 | C38: =C36*C37 -> 21 | D38: =D36*D37 -> 16 | E38: =E36*E37 -> 6 | F38: =F36*F37 -> 13 | G38: =G36*G37 -> 4 | H38: =H36*H37 -> 2 | I38: =I36*I37 -> 4 | ... M38: =M36*M37 -> 0 | N38: =SUM(B38:M38) -> 71
A42: TIME | B42: Motorcycle/Tuktuk | C42: Cars(<=5seats) | D42: Large Cars,4WD,SUVs | E42: Pickups/Vans | F42: Minibus/Matatus(<=14seat | G42: Small bus(14-33seat) | H42: Large bus(>33seat) | I42: Light Trucks(2axles) | J42: Medium Trucks(2axle,Double rear wheel) | K42: Heavy Trucks(3, 4 axles) | L42: Artics/draw-bar trucks | M42: Others (e.g tractors) | N42: TOTALS
A43: 8:45-9:00
A44: ='7-8AM'!A44 -> Maili Tisa Bound | B44: 9 | C44: 15 | D44: 7 | E44: 4 | F44: 9 | G44: 0 | H44: 0 | I44: 2 | J44: 1 | K44: 1 | L44: 0 | M44: 0 | N44: =SUM(B44:M44) -> 48
A45: ='7-8AM'!A45 -> Kitale Bound | B45: 18 | C45: 13 | D45: 6 | E45: 6 | F45: 6 | G45: 0 | H45: 0 | I45: 1 | J45: 1 | K45: 0 | L45: 0 | M45: 0 | N45: =SUM(B45:M45) -> 51
A46: VEHICLES | B46: =SUM(B44:B45) -> 27 | C46: =SUM(C44:C45) -> 28 | D46: =SUM(D44:D45) -> 13 | E46: =SUM(E44:E45) -> 10 | F46: =SUM(F44:F45) -> 15 | G46: =SUM(G44:G45) -> 0 | H46: =SUM(H44:H45) -> 0 | I46: =SUM(I44:I45) -> 3 | ... M46: =SUM(M44:M45) -> 0 | N46: =SUM(B46:M46) -> 99
A47: Conversion Factor | B47: 0 | C47: 1 | D47: 1 | E47: 1 | F47: 1 | G47: 1 | H47: 2 | I47: 1 | J47: 1 | K47: 2 | L47: 2 | M47: 1
A48: PCUs, Passenger Car Units | B48: =B46*B47 -> 0 | C48: =C46*C47 -> 28 | D48: =D46*D47 -> 13 | E48: =E46*E47 -> 10 | F48: =F46*F47 -> 15 | G48: =G46*G47 -> 0 | H48: =H46*H47 -> 0 | I48: =I46*I47 -> 3 | ... M48: =M46*M47 -> 0 | N48: =SUM(B48:M48) -> 73
A52: HOURLY (1HR) SUMMARY
A54: TIME | B54: Motorcycle/Tuktuk | C54: Cars(<=5seats) | D54: Large Cars,4WD,SUVs | E54: Pickups/Vans | F54: Minibus/Matatus(<=14seat | G54: Small bus(14-33seat) | H54: Large bus(>33seat) | I54: Light Trucks(2axles) | J54: Medium Trucks(2axle,Double rear wheel) | K54: Heavy Trucks(3, 4 axles) | L54: Artics/draw-bar trucks | M54: Others (e.g tractors) | N54: TOTALS
A55: 08 AM to 09 AM
A56: ='7-8AM'!A56 -> Maili Tisa Bound | B56: =B14+B24+B34+B44 -> 56 | C56: =C14+C24+C34+C44 -> 57 | D56: =D14+D24+D34+D44 -> 25 | E56: =E14+E24+E34+E44 -> 19 | F56: =F14+F24+F34+F44 -> 26 | G56: =G14+G24+G34+G44 -> 6 | H56: =H14+H24+H34+H44 -> 2 | I56: =I14+I24+I34+I44 -> 7 | ... M56: =M14+M24+M34+M44 -> 0 | N56: =SUM(B56:M56) -> 207
A57: ='7-8AM'!A57 -> Kitale Bound | B57: =B15+B25+B35+B45 -> 58 | C57: =C15+C25+C35+C45 -> 48 | D57: =D15+D25+D35+D45 -> 40 | E57: =E15+E25+E35+E45 -> 16 | F57: =F15+F25+F35+F45 -> 25 | G57: =G15+G25+G35+G45 -> 1 | H57: =H15+H25+H35+H45 -> 1 | I57: =I15+I25+I35+I45 -> 1 | ... M57: =M15+M25+M35+M45 -> 0 | N57: =SUM(B57:M57) -> 195
...

Sheet 9-10AM
A1: 09:00AM-10:00AM
A3: ='7-8AM'!A3 -> ROAD: JN A8 MAILI TISA-KITALE (B14) ROAD
A5: ='7-8AM'!A5 -> SITE: JN A8 MAILI TISA-KITALE (B14) ROAD
A6: ='7-8AM'!A6 -> PROJECT: PROPOSED FUEL SERVICE STATION
A7: ='7-8AM'!A7 -> C/O: GIDEON KAGO KARIUKI
A9: TRAFFIC VOLUME COUNTS DATA (RAW DATA)
A10: 15 MINUTES VOLUMES
A12: TIME | B12: Motorcycle/Tuktuk | C12: Cars(<=5seats) | D12: Large Cars,4WD,SUVs | E12: Pickups/Vans | F12: Minibus/Matatus(<=14seat | G12: Small bus(14-33seat) | H12: Large bus(>33seat) | I12: Light Trucks(2axles) | J12: Medium Trucks(2axle,Double rear wheel) | K12: Heavy Trucks(3, 4 axles) | L12: Artics/draw-bar trucks | M12: Others (e.g tractors) | N12: TOTALS
A13: 09:00-09:15
A14: ='7-8AM'!A14 -> Maili Tisa Bound | B14: 11 | C14: 8 | D14: 4 | E14: 2 | F14: 6 | G14: 0 | H14: 0 | I14: 1 | J14: 3 | K14: 1 | L14: 1 | M14: 0 | N14: =SUM(B14:M14) -> 37
A15: ='7-8AM'!A15 -> Kitale Bound | B15: 15 | C15: 6 | D15: 6 | E15: 1 | F15: 8 | G15: 0 | H15: 1 | I15: 1 | J15: 4 | K15: 1 | L15: 0 | M15: 0 | N15: =SUM(B15:M15) -> 43
A16: VEHICLES | B16: =SUM(B14:B15) -> 26 | C16: =SUM(C14:C15) -> 14 | D16: =SUM(D14:D15) -> 10 | E16: =SUM(E14:E15) -> 3 | F16: =SUM(F14:F15) -> 14 | G16: =SUM(G14:G15) -> 0 | H16: =SUM(H14:H15) -> 1 | I16: =SUM(I14:I15) -> 2 | ... M16: =SUM(M14:M15) -> 0 | N16: =SUM(B16:M16) -> 80
A17: Conversion Factor | B17: 0 | C17: 1 | D17: 1 | E17: 1 | F17: 1 | G17: 1 | H17: 2 | I17: 1 | J17: 1 | K17: 2 | L17: 2 | M17: 1
A18: PCUs, Passenger Car Units | B18: =B16*B17 -> 0 | C18: =C16*C17 -> 14 | D18: =D16*D17 -> 10 | E18: =E16*E17 -> 3 | F18: =F16*F17 -> 14 | G18: =G16*G17 -> 0 | H18: =H16*H17 -> 2 | I18: =I16*I17 -> 2 | ... M18: =M16*M17 -> 0 | N18: =SUM(B18:M18) -> 58
A22: TIME | B22: Motorcycle/Tuktuk | C22: Cars(<=5seats) | D22: Large Cars,4WD,SUVs | E22: Pickups/Vans | F22: Minibus/Matatus(<=14seat | G22: Small bus(14-33seat) | H22: Large bus(>33seat) | I22: Light Trucks(2axles) | J22: Medium Trucks(2axle,Double rear wheel) | K22: Heavy Trucks(3, 4 axles) | L22: Artics/draw-bar trucks | M22: Others (e.g tractors) | N22: TOTALS
A23: 9:15-9:30
A24: ='7-8AM'!A24 -> Maili Tisa Bound | B24: 14 | C24: 11 | D24: 4 | E24: 8 | F24: 4 | G24: 0 | H24: 0 | I24: 1 | J24: 2 | K24: 1 | L24: 0 | M24: 0 | N24: =SUM(B24:M24) -> 45
A25: ='7-8AM'!A25 -> Kitale Bound | B25: 12 | C25: 7 | D25: 3 | E25: 1 | F25: 9 | G25: 1 | H25: 1 | I25: 2 | J25: 1 | K25: 0 | L25: 0 | M25: 0 | N25: =SUM(B25:M25) -> 37
A26: VEHICLES | B26: =SUM(B24:B25) -> 26 | C26: =SUM(C24:C25) -> 18 | D26: =SUM(D24:D25) -> 7 | E26: =SUM(E24:E25) -> 9 | F26: =SUM(F24:F25) -> 13 | G26: =SUM(G24:G25) -> 1 | H26: =SUM(H24:H25) -> 1 | I26: =SUM(I24:I25) -> 3 | ... M26: =SUM(M24:M25) -> 0 | N26: =SUM(B26:M26) -> 82
A27: Conversion Factor | B27: 0 | C27: 1 | D27: 1 | E27: 1 | F27: 1 | G27: 1 | H27: 2 | I27: 1 | J27: 1 | K27: 2 | L27: 2 | M27: 1
A28: PCUs, Passenger Car Units | B28: =B26*B27 -> 0 | C28: =C26*C27 -> 18 | D28: =D26*D27 -> 7 | E28: =E26*E27 -> 9 | F28: =F26*F27 -> 13 | G28: =G26*G27 -> 1 | H28: =H26*H27 -> 2 | I28: =I26*I27 -> 3 | ... M28: =M26*M27 -> 0 | N28: =SUM(B28:M28) -> 58
A32: TIME | B32: Motorcycle/Tuktuk | C32: Cars(<=5seats) | D32: Large Cars,4WD,SUVs | E32: Pickups/Vans | F32: Minibus/Matatus(<=14seat | G32: Small bus(14-33seat) | H32: Large bus(>33seat) | I32: Light Trucks(2axles) | J32: Medium Trucks(2axle,Double rear wheel) | K32: Heavy Trucks(3, 4 axles) | L32: Artics/draw-bar trucks | M32: Others (e.g tractors) | N32: TOTALS
A33: 9:30-9:45
A34: ='7-8AM'!A34 -> Maili Tisa Bound | B34: 13 | C34: 7 | D34: 6 | E34: 3 | F34: 7 | G34: 1 | H34: 0 | I34: 0 | J34: 3 | K34: 1 | L34: 0 | M34: 0 | N34: =SUM(B34:M34) -> 41
A35: ='7-8AM'!A35 -> Kitale Bound | B35: 15 | C35: 13 | D35: 7 | E35: 5 | F35: 9 | G35: 0 | H35: 0 | I35: 2 | J35: 4 | K35: 1 | L35: 0 | M35: 0 | N35: =SUM(B35:M35) -> 56
A36: VEHICLES | B36: =SUM(B34:B35) -> 28 | C36: =SUM(C34:C35) -> 20 | D36: =SUM(D34:D35) -> 13 | E36: =SUM(E34:E35) -> 8 | F36: =SUM(F34:F35) -> 16 | G36: =SUM(G34:G35) -> 1 | H36: =SUM(H34:H35) -> 0 | I36: =SUM(I34:I35) -> 2 | ... M36: =SUM(M34:M35) -> 0 | N36: =SUM(B36:M36) -> 97
A37: Conversion Factor | B37: 0 | C37: 1 | D37: 1 | E37: 1 | F37: 1 | G37: 1 | H37: 2 | I37: 1 | J37: 1 | K37: 2 | L37: 2 | M37: 1
A38: PCUs, Passenger Car Units | B38: =B36*B37 -> 0 | C38: =C36*C37 -> 20 | D38: =D36*D37 -> 13 | E38: =E36*E37 -> 8 | F38: =F36*F37 -> 16 | G38: =G36*G37 -> 1 | H38: =H36*H37 -> 0 | I38: =I36*I37 -> 2 | ... M38: =M36*M37 -> 0 | N38: =SUM(B38:M38) -> 71
A42: TIME | B42: Motorcycle/Tuktuk | C42: Cars(<=5seats) | D42: Large Cars,4WD,SUVs | E42: Pickups/Vans | F42: Minibus/Matatus(<=14seat | G42: Small bus(14-33seat) | H42: Large bus(>33seat) | I42: Light Trucks(2axles) | J42: Medium Trucks(2axle,Double rear wheel) | K42: Heavy Trucks(3, 4 axles) | L42: Artics/draw-bar trucks | M42: Others (e.g tractors) | N42: TOTALS
A43: 9:45-10:00
A44: ='7-8AM'!A44 -> Maili Tisa Bound | B44: 12 | C44: 12 | D44: 6 | E44: 3 | F44: 6 | G44: 0 | H44: 0 | I44: 0 | J44: 1 | K44: 0 | L44: 0 | M44: 0 | N44: =SUM(B44:M44) -> 40
A45: ='7-8AM'!A45 -> Kitale Bound | B45: 18 | C45: 18 | D45: 6 | E45: 5 | F45: 11 | G45: 0 | H45: 0 | I45: 0 | J45: 3 | K45: 1 | L45: 0 | M45: 0 | N45: =SUM(B45:M45) -> 62
A46: VEHICLES | B46: =SUM(B44:B45) -> 30 | C46: =SUM(C44:C45) -> 30 | D46: =SUM(D44:D45) -> 12 | E46: =SUM(E44:E45) -> 8 | F46: =SUM(F44:F45) -> 17 | G46: =SUM(G44:G45) -> 0 | H46: =SUM(H44:H45) -> 0 | I46: =SUM(I44:I45) -> 0 | ... M46: =SUM(M44:M45) -> 0 | N46: =SUM(B46:M46) -> 102
A47: Conversion Factor | B47: 0 | C47: 1 | D47: 1 | E47: 1 | F47: 1 | G47: 1 | H47: 2 | I47: 1 | J47: 1 | K47: 2 | L47: 2 | M47: 1
A48: PCUs, Passenger Car Units | B48: =B46*B47 -> 0 | C48: =C46*C47 -> 30 | D48: =D46*D47 -> 12 | E48: =E46*E47 -> 8 | F48: =F46*F47 -> 17 | G48: =G46*G47 -> 0 | H48: =H46*H47 -> 0 | I48: =I46*I47 -> 0 | ... M48: =M46*M47 -> 0 | N48: =SUM(B48:M48) -> 73
A52: HOURLY (1HR) SUMMARY
A54: TIME | B54: Motorcycle/Tuktuk | C54: Cars(<=5seats) | D54: Large Cars,4WD,SUVs | E54: Pickups/Vans | F54: Minibus/Matatus(<=14seat | G54: Small bus(14-33seat) | H54: Large bus(>33seat) | I54: Light Trucks(2axles) | J54: Medium Trucks(2axle,Double rear wheel) | K54: Heavy Trucks(3, 4 axles) | L54: Artics/draw-bar trucks | M54: Others (e.g tractors) | N54: TOTALS
A55: 09 AM to 10 AM
A56: ='7-8AM'!A56 -> Maili Tisa Bound | B56: =B14+B24+B34+B44 -> 50 | C56: =SUM(C14,C24,C34,C44) -> 38 | D56: =SUM(D14,D24,D34,D44) -> 20 | E56: =SUM(E14,E24,E34,E44) -> 16 | F56: =SUM(F14,F24,F34,F44) -> 23 | G56: =SUM(G14,G24,G34,G44) -> 1 | H56: =SUM(H14,H24,H34,H44) -> 0 | I56: =SUM(I14,I24,I34,I44) -> 2 | J56: =SUM(J14,J24,J34,J44) -> 9 | ... M56: =SUM(M14,M24,M34,M44) -> 0 | N56: =SUM(B56:M56) -> 163
A57: ='7-8AM'!A57 -> Kitale Bound | B57: =SUM(B15,B25,B35,B45) -> 60 | C57: =SUM(C15,C25,C35,C45) -> 44 | D57: =SUM(D15,D25,D35,D45) -> 22 | E57: =SUM(E15,E25,E35,E45) -> 12 | F57: =SUM(F15,F25,F35,F45) -> 37 | G57: =SUM(G15,G25,G35,G45) -> 1 | H57: =SUM(H15,H25,H35,H45) -> 2 | I57: =SUM(I15,I25,I35,I45) -> 5 | ... M57: =SUM(M15,M25,M35,M45) -> 0 | N57: =SUM(B57:M57) -> 198
...

Sheet 10-11AM
A1: 10:00AM-11:00AM
A3: ='7-8AM'!A3 -> ROAD: JN A8 MAILI TISA-KITALE (B14) ROAD
A5: ='7-8AM'!A5 -> SITE: JN A8 MAILI TISA-KITALE (B14) ROAD
A6: ='7-8AM'!A6 -> PROJECT: PROPOSED FUEL SERVICE STATION
A7: ='7-8AM'!A7 -> C/O: GIDEON KAGO KARIUKI
A9: TRAFFIC VOLUME COUNTS DATA (RAW DATA)
A10: 15 MINUTES VOLUMES
A12: TIME | B12: Motorcycle/Tuktuk | C12: Cars(<=5seats) | D12: Large Cars,4WD,SUVs | E12: Pickups/Vans | F12: Minibus/Matatus(<=14seat | G12: Small bus(14-33seat) | H12: Large bus(>33seat) | I12: Light Trucks(2axles) | J12: Medium Trucks(2axle,Double rear wheel) | K12: Heavy Trucks(3, 4 axles) | L12: Artics/draw-bar trucks | M12: Others (e.g tractors) | N12: TOTALS
A13: 10:00-10:15
A14: ='7-8AM'!A14 -> Maili Tisa Bound | B14: 16 | C14: 10 | D14: 15 | E14: 4 | F14: 6 | G14: 1 | H14: 1 | I14: 0 | J14: 2 | K14: 1 | L14: 0 | M14: 0 | N14: =SUM(B14:M14) -> 56
A15: ='7-8AM'!A15 -> Kitale Bound | B15: 13 | C15: 16 | D15: 7 | E15: 9 | F15: 4 | G15: 0 | H15: 0 | I15: 1 | J15: 1 | K15: 0 | L15: 0 | M15: 0 | N15: =SUM(B15:M15) -> 51
A16: VEHICLES | B16: =SUM(B14:B15) -> 29 | C16: =SUM(C14:C15) -> 26 | D16: =SUM(D14:D15) -> 22 | E16: =SUM(E14:E15) -> 13 | F16: =SUM(F14:F15) -> 10 | G16: =SUM(G14:G15) -> 1 | H16: =SUM(H14:H15) -> 1 | I16: =SUM(I14:I15) -> 1 | ... M16: =SUM(M14:M15) -> 0 | N16: =SUM(B16:M16) -> 107
A17: Conversion Factor | B17: 0 | C17: 1 | D17: 1 | E17: 1 | F17: 1 | G17: 1 | H17: 2 | I17: 1 | J17: 1 | K17: 2 | L17: 2 | M17: 1
A18: PCUs, Passenger Car Units | B18: =B16*B17 -> 0 | C18: =C16*C17 -> 26 | D18: =D16*D17 -> 22 | E18: =E16*E17 -> 13 | F18: =F16*F17 -> 10 | G18: =G16*G17 -> 1 | H18: =H16*H17 -> 2 | I18: =I16*I17 -> 1 | ... M18: =M16*M17 -> 0 | N18: =SUM(B18:M18) -> 80
A22: TIME | B22: Motorcycle/Tuktuk | C22: Cars(<=5seats) | D22: Large Cars,4WD,SUVs | E22: Pickups/Vans | F22: Minibus/Matatus(<=14seat | G22: Small bus(14-33seat) | H22: Large bus(>33seat) | I22: Light Trucks(2axles) | J22: Medium Trucks(2axle,Double rear wheel) | K22: Heavy Trucks(3, 4 axles) | L22: Artics/draw-bar trucks | M22: Others (e.g tractors) | N22: TOTALS
A23: 10:15-10:30
A24: ='7-8AM'!A24 -> Maili Tisa Bound | B24: 12 | C24: 8 | D24: 7 | E24: 10 | F24: 6 | G24: 1 | H24: 1 | I24: 0 | J24: 1 | K24: 0 | L24: 0 | M24: 0 | N24: =SUM(B24:M24) -> 46
A25: ='7-8AM'!A25 -> Kitale Bound | B25: 16 | C25: 7 | D25: 6 | E25: 4 | F25: 9 | G25: 0 | H25: 0 | I25: 1 | J25: 1 | K25: 1 | L25: 1 | M25: 0 | N25: =SUM(B25:M25) -> 46
A26: VEHICLES | B26: 1 | C26: =SUM(C24:C25) -> 15 | D26: =SUM(D24:D25) -> 13 | E26: =SUM(E24:E25) -> 14 | F26: =SUM(F24:F25) -> 15 | G26: =SUM(G24:G25) -> 1 | H26: =SUM(H24:H25) -> 1 | I26: =SUM(I24:I25) -> 1 | J26: =SUM(J24:J25) -> 2 | ... M26: =SUM(M24:M25) -> 0 | N26: =SUM(B26:M26) -> 65
A27: Conversion Factor | B27: 0 | C27: 1 | D27: 1 | E27: 1 | F27: 1 | G27: 1 | H27: 2 | I27: 1 | J27: 1 | K27: 2 | L27: 2 | M27: 1
A28: PCUs, Passenger Car Units | B28: =B26*B27 -> 0 | C28: =C26*C27 -> 15 | D28: =D26*D27 -> 13 | E28: =E26*E27 -> 14 | F28: =F26*F27 -> 15 | G28: =G26*G27 -> 1 | H28: =H26*H27 -> 2 | I28: =I26*I27 -> 1 | ... M28: =M26*M27 -> 0 | N28: =SUM(B28:M28) -> 67
A32: TIME | B32: Motorcycle/Tuktuk | C32: Cars(<=5seats) | D32: Large Cars,4WD,SUVs | E32: Pickups/Vans | F32: Minibus/Matatus(<=14seat | G32: Small bus(14-33seat) | H32: Large bus(>33seat) | I32: Light Trucks(2axles) | J32: Medium Trucks(2axle,Double rear wheel) | K32: Heavy Trucks(3, 4 axles) | L32: Artics/draw-bar trucks | M32: Others (e.g tractors) | N32: TOTALS
A33: 10:30-10:45
A34: ='7-8AM'!A34 -> Maili Tisa Bound | B34: 11 | C34: 12 | D34: 9 | E34: 4 | F34: 8 | G34: 0 | H34: 0 | I34: 1 | J34: 1 | K34: 1 | L34: 0 | M34: 0 | N34: =SUM(B34:M34) -> 47
A35: ='7-8AM'!A35 -> Kitale Bound | B35: 15 | C35: 13 | D35: 10 | E35: 6 | F35: 3 | G35: 2 | H35: 1 | I35: 0 | J35: 1 | K35: 0 | L35: 0 | M35: 0 | N35: =SUM(B35:M35) -> 51
A36: VEHICLES | B36: =SUM(B34:B35) -> 26 | C36: =SUM(C34:C35) -> 25 | D36: =SUM(D34:D35) -> 19 | E36: =SUM(E34:E35) -> 10 | F36: =SUM(F34:F35) -> 11 | G36: =SUM(G34:G35) -> 2 | H36: 0 | I36: =SUM(I34:I35) -> 1 | J36: =SUM(J34:J35) -> 2 | K36: =SUM(K34:K35) -> 1 | L36: =SUM(L34:L35) -> 0 | M36: =SUM(M34:M35) -> 0 | N36: =SUM(B36:M36) -> 97
A37: Conversion Factor | B37: 0 | C37: 1 | D37: 1 | E37: 1 | F37: 1 | G37: 1 | H37: 2 | I37: 1 | J37: 1 | K37: 2 | L37: 2 | M37: 1
A38: PCUs, Passenger Car Units | B38: =B36*B37 -> 0 | C38: =C36*C37 -> 25 | D38: =D36*D37 -> 19 | E38: =E36*E37 -> 10 | F38: =F36*F37 -> 11 | G38: =G36*G37 -> 2 | H38: =H36*H37 -> 0 | I38: =I36*I37 -> 1 | ... M38: =M36*M37 -> 0 | N38: =SUM(B38:M38) -> 72
A42: TIME | B42: Motorcycle/Tuktuk | C42: Cars(<=5seats) | D42: Large Cars,4WD,SUVs | E42: Pickups/Vans | F42: Minibus/Matatus(<=14seat | G42: Small bus(14-33seat) | H42: Large bus(>33seat) | I42: Light Trucks(2axles) | J42: Medium Trucks(2axle,Double rear wheel) | K42: Heavy Trucks(3, 4 axles) | L42: Artics/draw-bar trucks | M42: Others (e.g tractors) | N42: TOTALS
A43: 10:45-11:00
A44: ='7-8AM'!A44 -> Maili Tisa Bound | B44: 14 | C44: 12 | D44: 6 | E44: 2 | F44: 8 | G44: 2 | H44: 1 | I44: 1 | J44: 4 | K44: 1 | L44: 0 | M44: 0 | N44: =SUM(B44:M44) -> 51
A45: ='7-8AM'!A45 -> Kitale Bound | B45: 11 | C45: 13 | D45: 7 | E45: 6 | F45: 7 | G45: 4 | H45: 0 | I45: 1 | J45: 1 | K45: 0 | L45: 0 | M45: 0 | N45: =SUM(B45:M45) -> 50
A46: VEHICLES | B46: =SUM(B44:B45) -> 25 | C46: =SUM(C44:C45) -> 25 | D46: =SUM(D44:D45) -> 13 | E46: =SUM(E44:E45) -> 8 | F46: =SUM(F44:F45) -> 15 | G46: =SUM(G44:G45) -> 6 | H46: =SUM(H44:H45) -> 1 | I46: =SUM(I44:I45) -> 2 | ... M46: =SUM(M44:M45) -> 0 | N46: =SUM(B46:M46) -> 101
A47: Conversion Factor | B47: 0 | C47: 1 | D47: 1 | E47: 1 | F47: 1 | G47: 1 | H47: 2 | I47: 1 | J47: 1 | K47: 2 | L47: 2 | M47: 1
A48: PCUs, Passenger Car Units | B48: =B46*B47 -> 0 | C48: =C46*C47 -> 25 | D48: =D46*D47 -> 13 | E48: =E46*E47 -> 8 | F48: =F46*F47 -> 15 | G48: =G46*G47 -> 6 | H48: =H46*H47 -> 2 | I48: =I46*I47 -> 2 | ... M48: =M46*M47 -> 0 | N48: =SUM(B48:M48) -> 78
A52: HOURLY (1HR) SUMMARY
A54: TIME | B54: Motorcycle/Tuktuk | C54: Cars(<=5seats) | D54: Large Cars,4WD,SUVs | E54: Pickups/Vans | F54: Minibus/Matatus(<=14seat | G54: Small bus(14-33seat) | H54: Large bus(>33seat) | I54: Light Trucks(2axles) | J54: Medium Trucks(2axle,Double rear wheel) | K54: Heavy Trucks(3, 4 axles) | L54: Artics/draw-bar trucks | M54: Others (e.g tractors) | N54: TOTALS
A55: 10 AM to 11 AM
A56: ='7-8AM'!A56 -> Maili Tisa Bound | B56: =(B14+B24+B34+B44) -> 53 | C56: =(C14+C24+C34+C44) -> 42 | D56: =(D14+D24+D34+D44) -> 37 | E56: =(E14+E24+E34+E44) -> 20 | F56: =(F14+F24+F34+F44) -> 28 | G56: =(G14+G24+G34+G44) -> 4 | H56: =(H14+H24+H34+H44) -> 3 | I56: =(I14+I24+I34+I44) -> 2 | ... M56: =(M14+M24+M34+M44) -> 0 | N56: =SUM(B56:M56) -> 200
A57: ='7-8AM'!A57 -> Kitale Bound | B57: =(B15+B25+B35+B45) -> 55 | C57: =(C15+C25+C35+C45) -> 49 | D57: =(D15+D25+D35+D45) -> 30 | E57: =(E15+E25+E35+E45) -> 25 | F57: =(F15+F25+F35+F45) -> 23 | G57: =(G15+G25+G35+G45) -> 6 | H57: =(H15+H25+H35+H45) -> 1 | I57: =(I15+I25+I35+I45) -> 3 | ... M57: =(M15+M25+M35+M45) -> 0 | N57: =SUM(B57:M57) -> 198
...

Sheet 11-12PM
A1: 11:00 AM-12:00 NOON
A3: ='7-8AM'!A3 -> ROAD: JN A8 MAILI TISA-KITALE (B14) ROAD
A5: ='7-8AM'!A5 -> SITE: JN A8 MAILI TISA-KITALE (B14) ROAD
A6: ='7-8AM'!A6 -> PROJECT: PROPOSED FUEL SERVICE STATION
A7: ='7-8AM'!A7 -> C/O: GIDEON KAGO KARIUKI
A9: TRAFFIC VOLUME COUNTS DATA (RAW DATA)
A10: 15 MINUTES VOLUMES
A12: TIME | B12: Motorcycle/Tuktuk | C12: Cars(<=5seats) | D12: Large Cars,4WD,SUVs | E12: Pickups/Vans | F12: Minibus/Matatus(<=14seat | G12: Small bus(14-33seat) | H12: Large bus(>33seat) | I12: Light Trucks(2axles) | J12: Medium Trucks(2axle,Double rear wheel) | K12: Heavy Trucks(3, 4 axles) | L12: Artics/draw-bar trucks | M12: Others (e.g tractors) | N12: TOTALS
A13: 11:00-11:15
A14: ='7-8AM'!A14 -> Maili Tisa Bound | B14: 15 | C14: 14 | D14: 17 | E14: 8 | F14: 6 | G14: 1 | H14: 0 | I14: 0 | J14: 0 | K14: 1 | L14: 0 | M14: 0 | N14: =SUM(B14:M14) -> 62
A15: ='7-8AM'!A15 -> Kitale Bound | B15: 12 | C15: 15 | D15: 7 | E15: 2 | F15: 8 | G15: 0 | H15: 2 | I15: 2 | J15: 1 | K15: 0 | L15: 0 | M15: 0 | N15: =SUM(B15:M15) -> 49
A16: VEHICLES | B16: =SUM(B14:B15) -> 27 | C16: =SUM(C14:C15) -> 29 | D16: =SUM(D14:D15) -> 24 | E16: =SUM(E14:E15) -> 10 | F16: =SUM(F14:F15) -> 14 | G16: =SUM(G14:G15) -> 1 | H16: =SUM(H14:H15) -> 2 | I16: =SUM(I14:I15) -> 2 | ... M16: =SUM(M14:M15) -> 0 | N16: =SUM(B16:M16) -> 111
A17: Conversion Factor | B17: 0 | C17: 1 | D17: 1 | E17: 1 | F17: 1 | G17: 1 | H17: 2 | I17: 1 | J17: 1 | K17: 2 | L17: 2 | M17: 1
A18: PCUs, Passenger Car Units | B18: =B16*B17 -> 0 | C18: =C16*C17 -> 29 | D18: =D16*D17 -> 24 | E18: =E16*E17 -> 10 | F18: =F16*F17 -> 14 | G18: =G16*G17 -> 1 | H18: =H16*H17 -> 4 | I18: =I16*I17 -> 2 | ... M18: =M16*M17 -> 0 | N18: =SUM(B18:M18) -> 87
A22: TIME | B22: Motorcycle/Tuktuk | C22: Cars(<=5seats) | D22: Large Cars,4WD,SUVs | E22: Pickups/Vans | F22: Minibus/Matatus(<=14seat | G22: Small bus(14-33seat) | H22: Large bus(>33seat) | I22: Light Trucks(2axles) | J22: Medium Trucks(2axle,Double rear wheel) | K22: Heavy Trucks(3, 4 axles) | L22: Artics/draw-bar trucks | M22: Others (e.g tractors) | N22: TOTALS
A23: 11:15-11:30
A24: ='7-8AM'!A24 -> Maili Tisa Bound | B24: 15 | C24: 15 | D24: 7 | E24: 5 | F24: 2 | G24: 2 | H24: 0 | I24: 1 | J24: 2 | K24: 0 | L24: 0 | M24: 0 | N24: =SUM(B24:M24) -> 49
A25: ='7-8AM'!A25 -> Kitale Bound | B25: 16 | C25: 20 | D25: 9 | E25: 4 | F25: 6 | G25: 0 | H25: 0 | I25: 0 | J25: 1 | K25: 1 | L25: 1 | M25: 0 | N25: =SUM(B25:M25) -> 58
A26: VEHICLES | B26: =SUM(B24:B25) -> 31 | C26: =SUM(C24:C25) -> 35 | D26: =SUM(D24:D25) -> 16 | E26: =SUM(E24:E25) -> 9 | F26: =SUM(F24:F25) -> 8 | G26: =SUM(G24:G25) -> 2 | H26: =SUM(H24:H25) -> 0 | I26: =SUM(I24:I25) -> 1 | ... M26: =SUM(M24:M25) -> 0 | N26: =SUM(B26:M26) -> 107
A27: Conversion Factor | B27: 0 | C27: 1 | D27: 1 | E27: 1 | F27: 1 | G27: 1 | H27: 2 | I27: 1 | J27: 1 | K27: 2 | L27: 2 | M27: 1
A28: PCUs, Passenger Car Units | B28: =B26*B27 -> 0 | C28: =C26*C27 -> 35 | D28: =D26*D27 -> 16 | E28: =E26*E27 -> 9 | F28: =F26*F27 -> 8 | G28: =G26*G27 -> 2 | H28: =H26*H27 -> 0 | I28: =I26*I27 -> 1 | ... M28: =M26*M27 -> 0 | N28: =SUM(B28:M28) -> 78
A32: TIME | B32: Motorcycle/Tuktuk | C32: Cars(<=5seats) | D32: Large Cars,4WD,SUVs | E32: Pickups/Vans | F32: Minibus/Matatus(<=14seat | G32: Small bus(14-33seat) | H32: Large bus(>33seat) | I32: Light Trucks(2axles) | J32: Medium Trucks(2axle,Double rear wheel) | K32: Heavy Trucks(3, 4 axles) | L32: Artics/draw-bar trucks | M32: Others (e.g tractors) | N32: TOTALS
A33: 11:30-11:45
A34: ='7-8AM'!A34 -> Maili Tisa Bound | B34: 20 | C34: 23 | D34: 13 | E34: 7 | F34: 8 | G34: 0 | H34: 0 | I34: 4 | J34: 9 | K34: 3 | L34: 1 | M34: 1 | N34: =SUM(B34:M34) -> 89
A35: ='7-8AM'!A35 -> Kitale Bound | B35: 12 | C35: 14 | D35: 4 | E35: 6 | F35: 6 | G35: 0 | H35: 1 | I35: 0 | J35: 2 | K35: 1 | L35: 0 | M35: 0 | N35: =SUM(B35:M35) -> 46
A36: VEHICLES | B36: =SUM(B34:B35) -> 32 | C36: =SUM(C34:C35) -> 37 | D36: =SUM(D34:D35) -> 17 | E36: =SUM(E34:E35) -> 13 | F36: =SUM(F34:F35) -> 14 | G36: =SUM(G34:G35) -> 0 | H36: =SUM(H34:H35) -> 1 | I36: =SUM(I34:I35) -> 4 | ... M36: =SUM(M34:M35) -> 1 | N36: =SUM(B36:M36) -> 135
A37: Conversion Factor | B37: 0 | C37: 1 | D37: 1 | E37: 1 | F37: 1 | G37: 1 | H37: 2 | I37: 1 | J37: 1 | K37: 2 | L37: 2 | M37: 1
A38: PCUs, Passenger Car Units | B38: =B36*B37 -> 0 | C38: =C36*C37 -> 37 | D38: =D36*D37 -> 17 | E38: =E36*E37 -> 13 | F38: =F36*F37 -> 14 | G38: =G36*G37 -> 0 | H38: =H36*H37 -> 2 | I38: =I36*I37 -> 4 | ... M38: =M36*M37 -> 1 | N38: =SUM(B38:M38) -> 109
A42: TIME | B42: Motorcycle/Tuktuk | C42: Cars(<=5seats) | D42: Large Cars,4WD,SUVs | E42: Pickups/Vans | F42: Minibus/Matatus(<=14seat | G42: Small bus(14-33seat) | H42: Large bus(>33seat) | I42: Light Trucks(2axles) | J42: Medium Trucks(2axle,Double rear wheel) | K42: Heavy Trucks(3, 4 axles) | L42: Artics/draw-bar trucks | M42: Others (e.g tractors) | N42: TOTALS
A43: 11:45-12:00
A44: ='7-8AM'!A44 -> Maili Tisa Bound | B44: 16 | C44: 9 | D44: 5 | E44: 3 | F44: 4 | G44: 1 | H44: 0 | I44: 0 | J44: 1 | K44: 4 | L44: 0 | M44: 0 | N44: =SUM(B44:M44) -> 43
A45: ='7-8AM'!A45 -> Kitale Bound | B45: 9 | C45: 9 | D45: 12 | E45: 6 | F45: 8 | G45: 3 | H45: 2 | I45: 1 | J45: 1 | K45: 1 | L45: 0 | M45: 0 | N45: =SUM(B45:M45) -> 52
A46: VEHICLES | B46: =SUM(B44:B45) -> 25 | C46: 4 | D46: 1 | E46: =SUM(E44:E45) -> 9 | F46: =SUM(F44:F45) -> 12 | G46: =SUM(G44:G45) -> 4 | H46: =SUM(H44:H45) -> 2 | I46: =SUM(I44:I45) -> 1 | J46: =SUM(J44:J45) -> 2 | K46: =SUM(K44:K45) -> 5 | L46: =SUM(L44:L45) -> 0 | M46: =SUM(M44:M45) -> 0 | N46: =SUM(B46:M46) -> 65
A47: Conversion Factor | B47: 0 | C47: 1 | D47: 1 | E47: 1 | F47: 1 | G47: 1 | H47: 2 | I47: 1 | J47: 1 | K47: 2 | L47: 2 | M47: 1
A48: PCUs, Passenger Car Units | B48: =B46*B47 -> 0 | C48: =C46*C47 -> 4 | D48: =D46*D47 -> 1 | E48: =E46*E47 -> 9 | F48: =F46*F47 -> 12 | G48: =G46*G47 -> 4 | H48: =H46*H47 -> 4 | I48: =I46*I47 -> 1 | ... M48: =M46*M47 -> 0 | N48: =SUM(B48:M48) -> 47
A52: HOURLY (1HR) SUMMARY
A54: TIME | B54: Motorcycle/Tuktuk | C54: Cars(<=5seats) | D54: Large Cars,4WD,SUVs | E54: Pickups/Vans | F54: Minibus/Matatus(<=14seat | G54: Small bus(14-33seat) | H54: Large bus(>33seat) | I54: Light Trucks(2axles) | J54: Medium Trucks(2axle,Double rear wheel) | K54: Heavy Trucks(3, 4 axles) | L54: Artics/draw-bar trucks | M54: Others (e.g tractors) | N54: TOTALS
A55: 11 AM to 12 PM
A56: ='7-8AM'!A56 -> Maili Tisa Bound | B56: =(B14+B24+B34+B44) -> 66 | C56: =(C14+C24+C34+C44) -> 61 | D56: =(D14+D24+D34+D44) -> 42 | E56: =(E14+E24+E34+E44) -> 23 | F56: =(F14+F24+F34+F44) -> 20 | G56: =(G14+G24+G34+G44) -> 4 | H56: =(H14+H24+H34+H44) -> 0 | I56: =(I14+I24+I34+I44) -> 5 | ... M56: =(M14+M24+M34+M44) -> 1 | N56: =SUM(B56:M56) -> 243
A57: ='7-8AM'!A57 -> Kitale Bound | B57: =(B15+B25+B35+B45) -> 49 | C57: =(C15+C25+C35+C45) -> 58 | D57: =(D15+D25+D35+D45) -> 32 | E57: =(E15+E25+E35+E45) -> 18 | F57: =(F15+F25+F35+F45) -> 28 | G57: =(G15+G25+G35+G45) -> 3 | H57: =(H15+H25+H35+H45) -> 5 | I57: =(I15+I25+I35+I45) -> 3 | ... M57: =(M15+M25+M35+M45) -> 0 | N57: =SUM(B57:M57) -> 205
...

Sheet 12-1PM
A1: 12:00 AM-1:00 PM
A3: ='7-8AM'!A3 -> ROAD: JN A8 MAILI TISA-KITALE (B14) ROAD
A5: ='7-8AM'!A5 -> SITE: JN A8 MAILI TISA-KITALE (B14) ROAD
A6: ='7-8AM'!A6 -> PROJECT: PROPOSED FUEL SERVICE STATION
A7: ='7-8AM'!A7 -> C/O: GIDEON KAGO KARIUKI
A9: TRAFFIC VOLUME COUNTS DATA (RAW DATA)
A10: 15 MINUTES VOLUMES
A12: TIME | B12: Motorcycle/Tuktuk | C12: Cars(<=5seats) | D12: Large Cars,4WD,SUVs | E12: Pickups/Vans | F12: Minibus/Matatus(<=14seat | G12: Small bus(14-33seat) | H12: Large bus(>33seat) | I12: Light Trucks(2axles) | J12: Medium Trucks(2axle,Double rear wheel) | K12: Heavy Trucks(3, 4 axles) | L12: Artics/draw-bar trucks | M12: Others (e.g tractors) | N12: TOTALS
A13: 12:00-12:15
A14: ='7-8AM'!A14 -> Maili Tisa Bound | B14: 14 | C14: 18 | D14: 14 | E14: 7 | F14: 6 | G14: 1 | H14: 1 | I14: 2 | J14: 1 | K14: 1 | L14: 1 | M14: 1 | N14: =SUM(B14:M14) -> 67
A15: ='7-8AM'!A15 -> Kitale Bound | B15: 16 | C15: 14 | D15: 9 | E15: 4 | F15: 9 | G15: 0 | H15: 1 | I15: 1 | J15: 3 | K15: 0 | L15: 0 | M15: 0 | N15: =SUM(B15:M15) -> 57
A16: VEHICLES | B16: =SUM(B14:B15) -> 30 | C16: =SUM(C14:C15) -> 32 | D16: =SUM(D14:D15) -> 23 | E16: =SUM(E14:E15) -> 11 | F16: =SUM(F14:F15) -> 15 | G16: =SUM(G14:G15) -> 1 | H16: =SUM(H14:H15) -> 2 | I16: =SUM(I14:I15) -> 3 | ... M16: =SUM(M14:M15) -> 1 | N16: =SUM(B16:M16) -> 124
A17: Conversion Factor | B17: 0 | C17: 1 | D17: 1 | E17: 1 | F17: 1 | G17: 1 | H17: 2 | I17: 1 | J17: 1 | K17: 2 | L17: 2 | M17: 1
A18: PCUs, Passenger Car Units | B18: =B16*B17 -> 0 | C18: =C16*C17 -> 32 | D18: =D16*D17 -> 23 | E18: =E16*E17 -> 11 | F18: =F16*F17 -> 15 | G18: =G16*G17 -> 1 | H18: =H16*H17 -> 4 | I18: =I16*I17 -> 3 | ... M18: =M16*M17 -> 1 | N18: =SUM(B18:M18) -> 98
A22: TIME | B22: Motorcycle/Tuktuk | C22: Cars(<=5seats) | D22: Large Cars,4WD,SUVs | E22: Pickups/Vans | F22: Minibus/Matatus(<=14seat | G22: Small bus(14-33seat) | H22: Large bus(>33seat) | I22: Light Trucks(2axles) | J22: Medium Trucks(2axle,Double rear wheel) | K22: Heavy Trucks(3, 4 axles) | L22: Artics/draw-bar trucks | M22: Others (e.g tractors) | N22: TOTALS
A23: 12:15-12:30
A24: ='7-8AM'!A24 -> Maili Tisa Bound | B24: 17 | C24: 12 | D24: 9 | E24: 2 | F24: 7 | G24: 0 | H24: 0 | I24: 1 | J24: 1 | K24: 1 | L24: 0 | M24: 0 | N24: =SUM(B24:M24) -> 50
A25: ='7-8AM'!A25 -> Kitale Bound | B25: 13 | C25: 14 | D25: 6 | E25: 5 | F25: 6 | G25: 1 | H25: 0 | I25: 1 | J25: 1 | K25: 1 | L25: 0 | M25: 0 | N25: =SUM(B25:M25) -> 48
A26: VEHICLES | B26: =SUM(B24:B25) -> 30 | C26: =SUM(C24:C25) -> 26 | D26: =SUM(D24:D25) -> 15 | E26: =SUM(E24:E25) -> 7 | F26: =SUM(F24:F25) -> 13 | G26: =SUM(G24:G25) -> 1 | H26: =SUM(H24:H25) -> 0 | I26: =SUM(I24:I25) -> 2 | ... M26: =SUM(M24:M25) -> 0 | N26: =SUM(B26:M26) -> 98
A27: Conversion Factor | B27: 0 | C27: 1 | D27: 1 | E27: 1 | F27: 1 | G27: 1 | H27: 2 | I27: 1 | J27: 1 | K27: 2 | L27: 2 | M27: 1
A28: PCUs, Passenger Car Units | B28: =B26*B27 -> 0 | C28: =C26*C27 -> 26 | D28: =D26*D27 -> 15 | E28: =E26*E27 -> 7 | F28: =F26*F27 -> 13 | G28: =G26*G27 -> 1 | H28: =H26*H27 -> 0 | I28: =I26*I27 -> 2 | ... M28: =M26*M27 -> 0 | N28: =SUM(B28:M28) -> 70
A32: TIME | B32: Motorcycle/Tuktuk | C32: Cars(<=5seats) | D32: Large Cars,4WD,SUVs | E32: Pickups/Vans | F32: Minibus/Matatus(<=14seat | G32: Small bus(14-33seat) | H32: Large bus(>33seat) | I32: Light Trucks(2axles) | J32: Medium Trucks(2axle,Double rear wheel) | K32: Heavy Trucks(3, 4 axles) | L32: Artics/draw-bar trucks | M32: Others (e.g tractors) | N32: TOTALS
A33: 12:30-12:45
A34: ='7-8AM'!A34 -> Maili Tisa Bound | B34: 18 | C34: 14 | D34: 3 | E34: 4 | F34: 7 | G34: 4 | H34: 1 | I34: 0 | J34: 2 | K34: 1 | L34: 0 | M34: 0 | N34: =SUM(B34:M34) -> 54
A35: ='7-8AM'!A35 -> Kitale Bound | B35: 11 | C35: 16 | D35: 6 | E35: 4 | F35: 7 | G35: 0 | H35: 0 | I35: 0 | J35: 4 | K35: 0 | L35: 1 | M35: 0 | N35: =SUM(B35:M35) -> 49
A36: VEHICLES | B36: 12 | C36: 1 | D36: 4 | E36: 3 | F36: 0 | G36: 0 | H36: =SUM(H34:H35) -> 1 | I36: =SUM(I34:I35) -> 0 | J36: =SUM(J34:J35) -> 6 | K36: =SUM(K34:K35) -> 1 | L36: =SUM(L34:L35) -> 1 | M36: =SUM(M34:M35) -> 0 | N36: =SUM(B36:M36) -> 29
A37: Conversion Factor | B37: 0 | C37: 1 | D37: 1 | E37: 1 | F37: 1 | G37: 1 | H37: 2 | I37: 1 | J37: 1 | K37: 2 | L37: 2 | M37: 1
A38: PCUs, Passenger Car Units | B38: =B36*B37 -> 0 | C38: =C36*C37 -> 1 | D38: =D36*D37 -> 4 | E38: =E36*E37 -> 3 | F38: =F36*F37 -> 0 | G38: =G36*G37 -> 0 | H38: =H36*H37 -> 2 | I38: =I36*I37 -> 0 | ... M38: =M36*M37 -> 0 | N38: =SUM(B38:M38) -> 20
A42: TIME | B42: Motorcycle/Tuktuk | C42: Cars(<=5seats) | D42: Large Cars,4WD,SUVs | E42: Pickups/Vans | F42: Minibus/Matatus(<=14seat | G42: Small bus(14-33seat) | H42: Large bus(>33seat) | I42: Light Trucks(2axles) | J42: Medium Trucks(2axle,Double rear wheel) | K42: Heavy Trucks(3, 4 axles) | L42: Artics/draw-bar trucks | M42: Others (e.g tractors) | N42: TOTALS
A43: 12:45-1:00
A44: ='7-8AM'!A44 -> Maili Tisa Bound | B44: 15 | C44: 14 | D44: 7 | E44: 4 | F44: 6 | G44: 0 | H44: 0 | I44: 1 | J44: 4 | K44: 1 | L44: 0 | M44: 0 | N44: =SUM(B44:M44) -> 52
A45: ='7-8AM'!A45 -> Kitale Bound | B45: 9 | C45: 20 | D45: 13 | E45: 4 | F45: 9 | G45: 0 | H45: 3 | I45: 1 | J45: 3 | K45: 0 | L45: 1 | M45: 1 | N45: =SUM(B45:M45) -> 64
A46: VEHICLES | B46: =SUM(B44:B45) -> 24 | C46: =SUM(C44:C45) -> 34 | D46: =SUM(D44:D45) -> 20 | E46: =SUM(E44:E45) -> 8 | F46: =SUM(F44:F45) -> 15 | G46: =SUM(G44:G45) -> 0 | H46: =SUM(H44:H45) -> 3 | I46: =SUM(I44:I45) -> 2 | ... M46: =SUM(M44:M45) -> 1 | N46: =SUM(B46:M46) -> 116
A47: Conversion Factor | B47: 0 | C47: 1 | D47: 1 | E47: 1 | F47: 1 | G47: 1 | H47: 2 | I47: 1 | J47: 1 | K47: 2 | L47: 2 | M47: 1
A48: PCUs, Passenger Car Units | B48: =B46*B47 -> 0 | C48: =C46*C47 -> 34 | D48: =D46*D47 -> 20 | E48: =E46*E47 -> 8 | F48: =F46*F47 -> 15 | G48: =G46*G47 -> 0 | H48: =H46*H47 -> 6 | I48: =I46*I47 -> 2 | ... M48: =M46*M47 -> 1 | N48: =SUM(B48:M48) -> 97
A52: HOURLY (1HR) SUMMARY
A54: TIME | B54: Motorcycle/Tuktuk | C54: Cars(<=5seats) | D54: Large Cars,4WD,SUVs | E54: Pickups/Vans | F54: Minibus/Matatus(<=14seat | G54: Small bus(14-33seat) | H54: Large bus(>33seat) | I54: Light Trucks(2axles) | J54: Medium Trucks(2axle,Double rear wheel) | K54: Heavy Trucks(3, 4 axles) | L54: Artics/draw-bar trucks | M54: Others (e.g tractors) | N54: TOTALS
A55: 12PM to 01 PM
A56: ='7-8AM'!A56 -> Maili Tisa Bound | B56: =(B14+B24+B34+B44) -> 64 | C56: =(C14+C24+C34+C44) -> 58 | D56: =(D14+D24+D34+D44) -> 33 | E56: =(E14+E24+E34+E44) -> 17 | F56: =(F14+F24+F34+F44) -> 26 | G56: =(G14+G24+G34+G44) -> 5 | H56: =(H14+H24+H34+H44) -> 2 | I56: =(I14+I24+I34+I44) -> 4 | ... M56: =(M14+M24+M34+M44) -> 1 | N56: =SUM(B56:M56) -> 223
A57: ='7-8AM'!A57 -> Kitale Bound | B57: =(B15+B25+B35+B45) -> 49 | C57: =(C15+C25+C35+C45) -> 64 | D57: =(D15+D25+D35+D45) -> 34 | E57: =(E15+E25+E35+E45) -> 17 | F57: =(F15+F25+F35+F45) -> 31 | G57: =(G15+G25+G35+G45) -> 1 | H57: =(H15+H25+H35+H45) -> 4 | I57: =(I15+I25+I35+I45) -> 3 | ... M57: =(M15+M25+M35+M45) -> 1 | N57: =SUM(B57:M57) -> 218
...

Sheet 1-2PM
A1: 01:00PM - 02:00PM
A3: ='7-8AM'!A3 -> ROAD: JN A8 MAILI TISA-KITALE (B14) ROAD
A5: ='7-8AM'!A5 -> SITE: JN A8 MAILI TISA-KITALE (B14) ROAD
A6: ='7-8AM'!A6 -> PROJECT: PROPOSED FUEL SERVICE STATION
A7: ='7-8AM'!A7 -> C/O: GIDEON KAGO KARIUKI
A9: TRAFFIC VOLUME COUNTS DATA (RAW DATA)
A10: 15 MINUTES VOLUMES
A12: TIME | B12: Motorcycle/Tuktuk | C12: Cars(<=5seats) | D12: Large Cars,4WD,SUVs | E12: Pickups/Vans | F12: Minibus/Matatus(<=14seat | G12: Small bus(14-33seat) | H12: Large bus(>33seat) | I12: Light Trucks(2axles) | J12: Medium Trucks(2axle,Double rear wheel) | K12: Heavy Trucks(3, 4 axles) | L12: Artics/draw-bar trucks | M12: Others (e.g tractors) | N12: TOTALS
A13: 1:00-1:15
A14: ='7-8AM'!A14 -> Maili Tisa Bound | B14: 8 | C14: 15 | D14: 9 | E14: 4 | F14: 8 | G14: 0 | H14: 0 | I14: 0 | J14: 4 | K14: 0 | L14: 0 | M14: 1 | N14: =SUM(B14:M14) -> 49
A15: ='7-8AM'!A15 -> Kitale Bound | B15: 19 | C15: 20 | D15: 11 | E15: 7 | F15: 4 | G15: 1 | H15: 1 | I15: 0 | J15: 4 | K15: 1 | L15: 0 | M15: 0 | N15: =SUM(B15:M15) -> 68
A16: VEHICLES | B16: =SUM(B14:B15) -> 27 | C16: =SUM(C14:C15) -> 35 | D16: =SUM(D14:D15) -> 20 | E16: =SUM(E14:E15) -> 11 | F16: =SUM(F14:F15) -> 12 | G16: =SUM(G14:G15) -> 1 | H16: =SUM(H14:H15) -> 1 | I16: =SUM(I14:I15) -> 0 | ... M16: =SUM(M14:M15) -> 1 | N16: =SUM(B16:M16) -> 117
A17: Conversion Factor | B17: 0 | C17: 1 | D17: 1 | E17: 1 | F17: 1 | G17: 1 | H17: 2 | I17: 1 | J17: 1 | K17: 2 | L17: 2 | M17: 1
A18: PCUs, Passenger Car Units | B18: =B16*B17 -> 0 | C18: =C16*C17 -> 35 | D18: =D16*D17 -> 20 | E18: =E16*E17 -> 11 | F18: =F16*F17 -> 12 | G18: =G16*G17 -> 1 | H18: =H16*H17 -> 2 | I18: =I16*I17 -> 0 | ... M18: =M16*M17 -> 1 | N18: =SUM(B18:M18) -> 92
A22: TIME | B22: Motorcycle/Tuktuk | C22: Cars(<=5seats) | D22: Large Cars,4WD,SUVs | E22: Pickups/Vans | F22: Minibus/Matatus(<=14seat | G22: Small bus(14-33seat) | H22: Large bus(>33seat) | I22: Light Trucks(2axles) | J22: Medium Trucks(2axle,Double rear wheel) | K22: Heavy Trucks(3, 4 axles) | L22: Artics/draw-bar trucks | M22: Others (e.g tractors) | N22: TOTALS
A23: 1:15-1:30
A24: ='7-8AM'!A24 -> Maili Tisa Bound | B24: 16 | C24: 8 | D24: 12 | E24: 9 | F24: 4 | G24: 0 | H24: 0 | I24: 0 | J24: 4 | K24: 1 | L24: 0 | M24: 1 | N24: =SUM(B24:M24) -> 55
A25: ='7-8AM'!A25 -> Kitale Bound | B25: 21 | C25: 22 | D25: 6 | E25: 1 | F25: 8 | G25: 0 | H25: 0 | I25: 0 | J25: 4 | K25: 1 | L25: 1 | M25: 0 | N25: =SUM(B25:M25) -> 64
A26: VEHICLES | B26: =SUM(B24:B25) -> 37 | C26: =SUM(C24:C25) -> 30 | D26: =SUM(D24:D25) -> 18 | E26: =SUM(E24:E25) -> 10 | F26: =SUM(F24:F25) -> 12 | G26: =SUM(G24:G25) -> 0 | H26: =SUM(H24:H25) -> 0 | I26: =SUM(I24:I25) -> 0 | ... M26: =SUM(M24:M25) -> 1 | N26: =SUM(B26:M26) -> 119
A27: Conversion Factor | B27: 0 | C27: 1 | D27: 1 | E27: 1 | F27: 1 | G27: 1 | H27: 2 | I27: 1 | J27: 1 | K27: 2 | L27: 2 | M27: 1
A28: PCUs, Passenger Car Units | B28: =B26*B27 -> 0 | C28: =C26*C27 -> 30 | D28: =D26*D27 -> 18 | E28: =E26*E27 -> 10 | F28: =F26*F27 -> 12 | G28: =G26*G27 -> 0 | H28: =H26*H27 -> 0 | I28: =I26*I27 -> 0 | ... M28: =M26*M27 -> 1 | N28: =SUM(B28:M28) -> 85
A32: TIME | B32: Motorcycle/Tuktuk | C32: Cars(<=5seats) | D32: Large Cars,4WD,SUVs | E32: Pickups/Vans | F32: Minibus/Matatus(<=14seat | G32: Small bus(14-33seat) | H32: Large bus(>33seat) | I32: Light Trucks(2axles) | J32: Medium Trucks(2axle,Double rear wheel) | K32: Heavy Trucks(3, 4 axles) | L32: Artics/draw-bar trucks | M32: Others (e.g tractors) | N32: TOTALS
A33: 1:30-1:45
A34: ='7-8AM'!A34 -> Maili Tisa Bound | B34: 19 | C34: 12 | D34: 4 | E34: 3 | F34: 4 | G34: 1 | H34: 1 | I34: 0 | J34: 5 | K34: 1 | L34: 1 | M34: 0 | N34: =SUM(B34:M34) -> 51
A35: ='7-8AM'!A35 -> Kitale Bound | B35: 13 | C35: 14 | D35: 4 | E35: 2 | F35: 8 | G35: 1 | H35: 0 | I35: 0 | J35: 3 | K35: 0 | L35: 0 | M35: 0 | N35: =SUM(B35:M35) -> 45
A36: VEHICLES | B36: =SUM(B34:B35) -> 32 | C36: =SUM(C34:C35) -> 26 | D36: =SUM(D34:D35) -> 8 | E36: =SUM(E34:E35) -> 5 | F36: =SUM(F34:F35) -> 12 | G36: =SUM(G34:G35) -> 2 | H36: =SUM(H34:H35) -> 1 | I36: =SUM(I34:I35) -> 0 | ... M36: =SUM(M34:M35) -> 0 | N36: =SUM(B36:M36) -> 96
A37: Conversion Factor | B37: 0 | C37: 1 | D37: 1 | E37: 1 | F37: 1 | G37: 1 | H37: 2 | I37: 1 | J37: 1 | K37: 2 | L37: 2 | M37: 1
A38: PCUs, Passenger Car Units | B38: =B36*B37 -> 0 | C38: =C36*C37 -> 26 | D38: =D36*D37 -> 8 | E38: =E36*E37 -> 5 | F38: =F36*F37 -> 12 | G38: =G36*G37 -> 2 | H38: =H36*H37 -> 2 | I38: =I36*I37 -> 0 | ... M38: =M36*M37 -> 0 | N38: =SUM(B38:M38) -> 67
A42: TIME | B42: Motorcycle/Tuktuk | C42: Cars(<=5seats) | D42: Large Cars,4WD,SUVs | E42: Pickups/Vans | F42: Minibus/Matatus(<=14seat | G42: Small bus(14-33seat) | H42: Large bus(>33seat) | I42: Light Trucks(2axles) | J42: Medium Trucks(2axle,Double rear wheel) | K42: Heavy Trucks(3, 4 axles) | L42: Artics/draw-bar trucks | M42: Others (e.g tractors) | N42: TOTALS
A43: 1:45-2:00
A44: ='7-8AM'!A44 -> Maili Tisa Bound | B44: 16 | C44: 15 | D44: 3 | E44: 3 | F44: 9 | G44: 2 | H44: 1 | I44: 0 | J44: 1 | K44: 1 | L44: 0 | M44: 0 | N44: =SUM(B44:M44) -> 51
A45: ='7-8AM'!A45 -> Kitale Bound | B45: 22 | C45: 20 | D45: 7 | E45: 5 | F45: 7 | G45: 0 | H45: 0 | I45: 0 | J45: 3 | K45: 0 | L45: 0 | M45: 0 | N45: =SUM(B45:M45) -> 64
A46: VEHICLES | B46: =SUM(B44:B45) -> 38 | C46: =SUM(C44:C45) -> 35 | D46: =SUM(D44:D45) -> 10 | E46: =SUM(E44:E45) -> 8 | F46: =SUM(F44:F45) -> 16 | G46: =SUM(G44:G45) -> 2 | H46: =SUM(H44:H45) -> 1 | I46: =SUM(I44:I45) -> 0 | ... M46: =SUM(M44:M45) -> 0 | N46: =SUM(B46:M46) -> 115
A47: Conversion Factor | B47: 0 | C47: 1 | D47: 1 | E47: 1 | F47: 1 | G47: 1 | H47: 2 | I47: 1 | J47: 1 | K47: 2 | L47: 2 | M47: 1
A48: PCUs, Passenger Car Units | B48: =B46*B47 -> 0 | C48: =C46*C47 -> 35 | D48: =D46*D47 -> 10 | E48: =E46*E47 -> 8 | F48: =F46*F47 -> 16 | G48: =G46*G47 -> 2 | H48: =H46*H47 -> 2 | I48: =I46*I47 -> 0 | ... M48: =M46*M47 -> 0 | N48: =SUM(B48:M48) -> 79
A52: HOURLY (1HR) SUMMARY
A54: TIME | B54: Motorcycle/Tuktuk | C54: Cars(<=5seats) | D54: Large Cars,4WD,SUVs | E54: Pickups/Vans | F54: Minibus/Matatus(<=14seat | G54: Small bus(14-33seat) | H54: Large bus(>33seat) | I54: Light Trucks(2axles) | J54: Medium Trucks(2axle,Double rear wheel) | K54: Heavy Trucks(3, 4 axles) | L54: Artics/draw-bar trucks | M54: Others (e.g tractors) | N54: TOTALS
A55: 01 PM to 02 PM
A56: ='7-8AM'!A56 -> Maili Tisa Bound | B56: =(B14+B24+B34+B44) -> 59 | C56: =(C14+C24+C34+C44) -> 50 | D56: =(D14+D24+D34+D44) -> 28 | E56: =(E14+E24+E34+E44) -> 19 | F56: =(F14+F24+F34+F44) -> 25 | G56: =(G14+G24+G34+G44) -> 3 | H56: =(H14+H24+H34+H44) -> 2 | I56: =(I14+I24+I34+I44) -> 0 | ... M56: =(M14+M24+M34+M44) -> 2 | N56: =SUM(B56:M56) -> 206
A57: ='7-8AM'!A57 -> Kitale Bound | B57: =(B15+B25+B35+B45) -> 75 | C57: =(C15+C25+C35+C45) -> 76 | D57: =(D15+D25+D35+D45) -> 28 | E57: =(E15+E25+E35+E45) -> 15 | F57: =(F15+F25+F35+F45) -> 27 | G57: =(G15+G25+G35+G45) -> 2 | H57: =(H15+H25+H35+H45) -> 1 | I57: =(I15+I25+I35+I45) -> 0 | ... M57: =(M15+M25+M35+M45) -> 0 | N57: =SUM(B57:M57) -> 241
...

Sheet 2-3PM
A1: 02:00PM - 03:00PM
A3: ='7-8AM'!A3 -> ROAD: JN A8 MAILI TISA-KITALE (B14) ROAD
A5: ='7-8AM'!A5 -> SITE: JN A8 MAILI TISA-KITALE (B14) ROAD
A6: ='7-8AM'!A6 -> PROJECT: PROPOSED FUEL SERVICE STATION
A7: ='7-8AM'!A7 -> C/O: GIDEON KAGO KARIUKI
A9: TRAFFIC VOLUME COUNTS DATA (RAW DATA)
A10: 15 MINUTES VOLUMES
A12: TIME | B12: Motorcycle/Tuktuk | C12: Cars(<=5seats) | D12: Large Cars,4WD,SUVs | E12: Pickups/Vans | F12: Minibus/Matatus(<=14seat | G12: Small bus(14-33seat) | H12: Large bus(>33seat) | I12: Light Trucks(2axles) | J12: Medium Trucks(2axle,Double rear wheel) | K12: Heavy Trucks(3, 4 axles) | L12: Artics/draw-bar trucks | M12: Others (e.g tractors) | N12: TOTALS
A13: 2:00-2:15
A14: ='7-8AM'!A14 -> Maili Tisa Bound | B14: 22 | C14: 15 | D14: 3 | E14: 3 | F14: 4 | G14: 0 | H14: 1 | I14: 0 | J14: 2 | K14: 1 | L14: 0 | M14: 0 | N14: =SUM(B14:M14) -> 51
A15: ='7-8AM'!A15 -> Kitale Bound | B15: 19 | C15: 23 | D15: 5 | E15: 3 | F15: 8 | G15: 0 | H15: 0 | I15: 0 | J15: 6 | K15: 0 | L15: 0 | M15: 0 | N15: =SUM(B15:M15) -> 64
A16: VEHICLES | B16: =SUM(B14:B15) -> 41 | C16: =SUM(C14:C15) -> 38 | D16: =SUM(D14:D15) -> 8 | E16: =SUM(E14:E15) -> 6 | F16: =SUM(F14:F15) -> 12 | G16: =SUM(G14:G15) -> 0 | H16: =SUM(H14:H15) -> 1 | I16: =SUM(I14:I15) -> 0 | ... M16: =SUM(M14:M15) -> 0 | N16: =SUM(B16:M16) -> 115
A17: Conversion Factor | B17: 0 | C17: 1 | D17: 1 | E17: 1 | F17: 1 | G17: 1 | H17: 2 | I17: 1 | J17: 1 | K17: 2 | L17: 2 | M17: 1
A18: PCUs, Passenger Car Units | B18: =B16*B17 -> 0 | C18: =C16*C17 -> 38 | D18: =D16*D17 -> 8 | E18: =E16*E17 -> 6 | F18: =F16*F17 -> 12 | G18: =G16*G17 -> 0 | H18: =H16*H17 -> 2 | I18: =I16*I17 -> 0 | ... M18: =M16*M17 -> 0 | N18: =SUM(B18:M18) -> 76
A22: TIME | B22: Motorcycle/Tuktuk | C22: Cars(<=5seats) | D22: Large Cars,4WD,SUVs | E22: Pickups/Vans | F22: Minibus/Matatus(<=14seat | G22: Small bus(14-33seat) | H22: Large bus(>33seat) | I22: Light Trucks(2axles) | J22: Medium Trucks(2axle,Double rear wheel) | K22: Heavy Trucks(3, 4 axles) | L22: Artics/draw-bar trucks | M22: Others (e.g tractors) | N22: TOTALS
A23: 2:15-2:30
A24: ='7-8AM'!A24 -> Maili Tisa Bound | B24: 20 | C24: 9 | D24: 3 | E24: 4 | F24: 6 | G24: 0 | H24: 1 | I24: 0 | J24: 4 | K24: 0 | L24: 1 | M24: 0 | N24: =SUM(B24:M24) -> 48
A25: ='7-8AM'!A25 -> Kitale Bound | B25: 21 | C25: 14 | D25: 4 | E25: 1 | F25: 7 | G25: 0 | H25: 0 | I25: 0 | J25: 3 | K25: 0 | L25: 1 | M25: 0 | N25: =SUM(B25:M25) -> 51
A26: VEHICLES | B26: =SUM(B24:B25) -> 41 | C26: =SUM(C24:C25) -> 23 | D26: =SUM(D24:D25) -> 7 | E26: =SUM(E24:E25) -> 5 | F26: =SUM(F24:F25) -> 13 | G26: =SUM(G24:G25) -> 0 | H26: =SUM(H24:H25) -> 1 | I26: =SUM(I24:I25) -> 0 | ... M26: =SUM(M24:M25) -> 0 | N26: =SUM(B26:M26) -> 99
A27: Conversion Factor | B27: 0 | C27: 1 | D27: 1 | E27: 1 | F27: 1 | G27: 1 | H27: 2 | I27: 1 | J27: 1 | K27: 2 | L27: 2 | M27: 1
A28: PCUs, Passenger Car Units | B28: =B26*B27 -> 0 | C28: =C26*C27 -> 23 | D28: =D26*D27 -> 7 | E28: =E26*E27 -> 5 | F28: =F26*F27 -> 13 | G28: =G26*G27 -> 0 | H28: =H26*H27 -> 2 | I28: =I26*I27 -> 0 | ... M28: =M26*M27 -> 0 | N28: =SUM(B28:M28) -> 61
A32: TIME | B32: Motorcycle/Tuktuk | C32: Cars(<=5seats) | D32: Large Cars,4WD,SUVs | E32: Pickups/Vans | F32: Minibus/Matatus(<=14seat | G32: Small bus(14-33seat) | H32: Large bus(>33seat) | I32: Light Trucks(2axles) | J32: Medium Trucks(2axle,Double rear wheel) | K32: Heavy Trucks(3, 4 axles) | L32: Artics/draw-bar trucks | M32: Others (e.g tractors) | N32: TOTALS
A33: 2:30-2:45
A34: ='7-8AM'!A34 -> Maili Tisa Bound | B34: 24 | C34: 9 | D34: 8 | E34: 2 | F34: 10 | G34: 0 | H34: 0 | I34: 0 | J34: 6 | K34: 0 | L34: 0 | M34: 0 | N34: =SUM(B34:M34) -> 59
A35: ='7-8AM'!A35 -> Kitale Bound | B35: 29 | C35: 19 | D35: 1 | E35: 3 | F35: 6 | G35: 0 | H35: 1 | I35: 0 | J35: 3 | K35: 2 | L35: 0 | M35: 0 | N35: =SUM(B35:M35) -> 64
A36: VEHICLES | B36: =SUM(B34:B35) -> 53 | C36: =SUM(C34:C35) -> 28 | D36: =SUM(D34:D35) -> 9 | E36: =SUM(E34:E35) -> 5 | F36: =SUM(F34:F35) -> 16 | G36: =SUM(G34:G35) -> 0 | H36: =SUM(H34:H35) -> 1 | I36: =SUM(I34:I35) -> 0 | ... M36: =SUM(M34:M35) -> 0 | N36: =SUM(B36:M36) -> 123
A37: Conversion Factor | B37: 0 | C37: 1 | D37: 1 | E37: 1 | F37: 1 | G37: 1 | H37: 2 | I37: 1 | J37: 1 | K37: 2 | L37: 2 | M37: 1
A38: PCUs, Passenger Car Units | B38: =B36*B37 -> 0 | C38: =C36*C37 -> 28 | D38: =D36*D37 -> 9 | E38: =E36*E37 -> 5 | F38: =F36*F37 -> 16 | G38: =G36*G37 -> 0 | H38: =H36*H37 -> 2 | I38: =I36*I37 -> 0 | ... M38: =M36*M37 -> 0 | N38: =SUM(B38:M38) -> 73
A42: TIME | B42: Motorcycle/Tuktuk | C42: Cars(<=5seats) | D42: Large Cars,4WD,SUVs | E42: Pickups/Vans | F42: Minibus/Matatus(<=14seat | G42: Small bus(14-33seat) | H42: Large bus(>33seat) | I42: Light Trucks(2axles) | J42: Medium Trucks(2axle,Double rear wheel) | K42: Heavy Trucks(3, 4 axles) | L42: Artics/draw-bar trucks | M42: Others (e.g tractors) | N42: TOTALS
A43: 2:45-3:00
A44: ='7-8AM'!A44 -> Maili Tisa Bound | B44: 26 | C44: 12 | D44: 8 | E44: 3 | F44: 6 | G44: 0 | H44: 0 | I44: 1 | J44: 1 | K44: 1 | L44: 0 | M44: 0 | N44: =SUM(B44:M44) -> 58
A45: ='7-8AM'!A45 -> Kitale Bound | B45: 31 | C45: 19 | D45: 5 | E45: 3 | F45: 8 | G45: 0 | H45: 0 | I45: 0 | J45: 3 | K45: 2 | L45: 1 | M45: 0 | N45: =SUM(B45:M45) -> 72
A46: VEHICLES | B46: =SUM(B44:B45) -> 57 | C46: =SUM(C44:C45) -> 31 | D46: =SUM(D44:D45) -> 13 | E46: =SUM(E44:E45) -> 6 | F46: =SUM(F44:F45) -> 14 | G46: =SUM(G44:G45) -> 0 | H46: =SUM(H44:H45) -> 0 | I46: =SUM(I44:I45) -> 1 | ... M46: =SUM(M44:M45) -> 0 | N46: =SUM(B46:M46) -> 130
A47: Conversion Factor | B47: 0 | C47: 1 | D47: 1 | E47: 1 | F47: 1 | G47: 1 | H47: 2 | I47: 1 | J47: 1 | K47: 2 | L47: 2 | M47: 1
A48: PCUs, Passenger Car Units | B48: =B46*B47 -> 0 | C48: =C46*C47 -> 31 | D48: =D46*D47 -> 13 | E48: =E46*E47 -> 6 | F48: =F46*F47 -> 14 | G48: =G46*G47 -> 0 | H48: =H46*H47 -> 0 | I48: =I46*I47 -> 1 | ... M48: =M46*M47 -> 0 | N48: =SUM(B48:M48) -> 77
A52: HOURLY (1HR) SUMMARY
A54: TIME | B54: Motorcycle/Tuktuk | C54: Cars(<=5seats) | D54: Large Cars,4WD,SUVs | E54: Pickups/Vans | F54: Minibus/Matatus(<=14seat | G54: Small bus(14-33seat) | H54: Large bus(>33seat) | I54: Light Trucks(2axles) | J54: Medium Trucks(2axle,Double rear wheel) | K54: Heavy Trucks(3, 4 axles) | L54: Artics/draw-bar trucks | M54: Others (e.g tractors) | N54: TOTALS
A55: 02 PM to 03 PM
A56: ='7-8AM'!A56 -> Maili Tisa Bound | B56: =(B14+B24+B34+B44) -> 92 | C56: =(C14+C24+C34+C44) -> 45 | D56: =(D14+D24+D34+D44) -> 22 | E56: =(E14+E24+E34+E44) -> 12 | F56: =(F14+F24+F34+F44) -> 26 | G56: =(G14+G24+G34+G44) -> 0 | H56: =(H14+H24+H34+H44) -> 2 | I56: =(I14+I24+I34+I44) -> 1 | ... M56: =(M14+M24+M34+M44) -> 0 | N56: =SUM(B56:M56) -> 216
A57: ='7-8AM'!A57 -> Kitale Bound | B57: =(B15+B25+B35+B45) -> 100 | C57: =(C15+C25+C35+C45) -> 75 | D57: =(D15+D25+D35+D45) -> 15 | E57: =(E15+E25+E35+E45) -> 10 | F57: =(F15+F25+F35+F45) -> 29 | G57: =(G15+G25+G35+G45) -> 0 | H57: =(H15+H25+H35+H45) -> 1 | I57: =(I15+I25+I35+I45) -> 0 | ... M57: =(M15+M25+M35+M45) -> 0 | N57: =SUM(B57:M57) -> 251
...

Sheet 3-4PM
A1: 03:00 PM -04:00 PM
A3: ='7-8AM'!A3 -> ROAD: JN A8 MAILI TISA-KITALE (B14) ROAD
A5: ='7-8AM'!A5 -> SITE: JN A8 MAILI TISA-KITALE (B14) ROAD
A6: ='7-8AM'!A6 -> PROJECT: PROPOSED FUEL SERVICE STATION
A7: ='7-8AM'!A7 -> C/O: GIDEON KAGO KARIUKI
A9: TRAFFIC VOLUME COUNTS DATA (RAW DATA)
A10: 15 MINUTES VOLUMES
A12: TIME | B12: Motorcycle/Tuktuk | C12: Cars(<=5seats) | D12: Large Cars,4WD,SUVs | E12: Pickups/Vans | F12: Minibus/Matatus(<=14seat | G12: Small bus(14-33seat) | H12: Large bus(>33seat) | I12: Light Trucks(2axles) | J12: Medium Trucks(2axle,Double rear wheel) | K12: Heavy Trucks(3, 4 axles) | L12: Artics/draw-bar trucks | M12: Others (e.g tractors) | N12: TOTALS
A13: 3:00-3:15
A14: ='7-8AM'!A14 -> Maili Tisa Bound | B14: 23 | C14: 14 | D14: 7 | E14: 3 | F14: 3 | G14: 0 | H14: 0 | I14: 1 | J14: 1 | K14: 0 | L14: 0 | M14: 0 | N14: =SUM(B14:M14) -> 52
A15: ='7-8AM'!A15 -> Kitale Bound | B15: 16 | C15: 19 | D15: 4 | E15: 2 | F15: 4 | G15: 0 | H15: 2 | I15: 0 | J15: 1 | K15: 0 | L15: 0 | M15: 0 | N15: =SUM(B15:M15) -> 48
A16: VEHICLES | B16: =SUM(B14:B15) -> 39 | C16: =SUM(C14:C15) -> 33 | D16: =SUM(D14:D15) -> 11 | E16: =SUM(E14:E15) -> 5 | F16: =SUM(F14:F15) -> 7 | G16: =SUM(G14:G15) -> 0 | H16: =SUM(H14:H15) -> 2 | I16: =SUM(I14:I15) -> 1 | ... M16: =SUM(M14:M15) -> 0 | N16: =SUM(B16:M16) -> 100
A17: Conversion Factor | B17: 0 | C17: 1 | D17: 1 | E17: 1 | F17: 1 | G17: 1 | H17: 2 | I17: 1 | J17: 1 | K17: 2 | L17: 2 | M17: 1
A18: PCUs, Passenger Car Units | B18: =B16*B17 -> 0 | C18: =C16*C17 -> 33 | D18: =D16*D17 -> 11 | E18: =E16*E17 -> 5 | F18: =F16*F17 -> 7 | G18: =G16*G17 -> 0 | H18: =H16*H17 -> 4 | I18: =I16*I17 -> 1 | ... M18: =M16*M17 -> 0 | N18: =SUM(B18:M18) -> 63
A22: TIME | B22: Motorcycle/Tuktuk | C22: Cars(<=5seats) | D22: Large Cars,4WD,SUVs | E22: Pickups/Vans | F22: Minibus/Matatus(<=14seat | G22: Small bus(14-33seat) | H22: Large bus(>33seat) | I22: Light Trucks(2axles) | J22: Medium Trucks(2axle,Double rear wheel) | K22: Heavy Trucks(3, 4 axles) | L22: Artics/draw-bar trucks | M22: Others (e.g tractors) | N22: TOTALS
A23: 3:15-3:30
A24: ='7-8AM'!A24 -> Maili Tisa Bound | B24: 19 | C24: 16 | D24: 11 | E24: 9 | F24: 6 | G24: 0 | H24: 1 | I24: 1 | J24: 2 | K24: 0 | L24: 0 | M24: 0 | N24: =SUM(B24:M24) -> 65
A25: ='7-8AM'!A25 -> Kitale Bound | B25: 22 | C25: 12 | D25: 7 | E25: 4 | F25: 12 | G25: 2 | H25: 0 | I25: 0 | J25: 1 | K25: 1 | L25: 0 | M25: 0 | N25: =SUM(B25:M25) -> 61
A26: VEHICLES | B26: =SUM(B24:B25) -> 41 | C26: =SUM(C24:C25) -> 28 | D26: =SUM(D24:D25) -> 18 | E26: =SUM(E24:E25) -> 13 | F26: =SUM(F24:F25) -> 18 | G26: =SUM(G24:G25) -> 2 | H26: =SUM(H24:H25) -> 1 | I26: =SUM(I24:I25) -> 1 | ... M26: =SUM(M24:M25) -> 0 | N26: =SUM(B26:M26) -> 126
A27: Conversion Factor | B27: 0 | C27: 1 | D27: 1 | E27: 1 | F27: 1 | G27: 1 | H27: 2 | I27: 1 | J27: 1 | K27: 2 | L27: 2 | M27: 1
A28: PCUs, Passenger Car Units | B28: =B26*B27 -> 0 | C28: =C26*C27 -> 28 | D28: =D26*D27 -> 18 | E28: =E26*E27 -> 13 | F28: =F26*F27 -> 18 | G28: =G26*G27 -> 2 | H28: =H26*H27 -> 2 | I28: =I26*I27 -> 1 | ... M28: =M26*M27 -> 0 | N28: =SUM(B28:M28) -> 87
A32: TIME | B32: Motorcycle/Tuktuk | C32: Cars(<=5seats) | D32: Large Cars,4WD,SUVs | E32: Pickups/Vans | F32: Minibus/Matatus(<=14seat | G32: Small bus(14-33seat) | H32: Large bus(>33seat) | I32: Light Trucks(2axles) | J32: Medium Trucks(2axle,Double rear wheel) | K32: Heavy Trucks(3, 4 axles) | L32: Artics/draw-bar trucks | M32: Others (e.g tractors) | N32: TOTALS
A33: 3:30-3:45
A34: ='7-8AM'!A34 -> Maili Tisa Bound | B34: 23 | C34: 17 | D34: 6 | E34: 8 | F34: 6 | G34: 0 | H34: 0 | I34: 2 | J34: 1 | K34: 3 | L34: 0 | M34: 0 | N34: =SUM(B34:M34) -> 66
